Workbook

Sheet Übersicht
A2: STEIMER Feiertagsgrundlage Schweiz
A4: Kalenderjahr | B4: 2027 | D4: Prüfzeitraum 2026–2028
A6: AP18B-02 · V0.8 · TI/GR mit provisorischen RG-Ergänzungen
A8: 22 Kantone noch nicht erhoben. Erfasste Kantonsregeln bleiben bis zur Fachabnahme offen.
A9: CH/BE/AG unverändert. TI und GR mit Namensfeldern DE/FR/IT/RG ergänzt.
A10: GR nur kantonale Grundliste. Lokale Ruhetage nicht erhoben, VRG-Annahme dokumentiert.
A11: Gelbes Feld: Jahr ändern. Die Datumswerte werden in Excel neu berechnet.
A12: Im Feiertagskalender nach Gemeinwesen, Geltungsbereich oder Status filtern.
A13: Jede Regeländerung verlangt Fachstatus open und neue Prüfung. Alte Freigabe gilt nicht weiter.
A14: approved bezeichnet nur die angegebene frühere Fachfreigabe, nicht diese Arbeitsmappe.
A15: Quellenprüfung und Datenrelease bleiben getrennt. Neue Prüfereignisse sind candidate.
A16: Keine Makros, externen Datenverbindungen oder automatische Datenaktivierung.
A17: Sonntage gelten separat. Die Ansicht enthält benannte Feiertage, nicht jeden Sonntag.
A18: Gerichtsferien bleiben unverändert in der bestehenden Kalenderkomponente.
... A20: Kalender-App und Feiertagskarte gehören nicht zu AP18.
A23: Kontrolle | B23: Anzahl
A24: Gemeinwesen | B24: =COUNTA('Gemeinwesen'!$A$7:$A$33) -> 27 | D24: Stand: 13. September 2026
A25: Referenz-Feiertagsregeln | B25: =COUNTIFS('Feiertagsregeln'!$R$7:$R$96,"approved") -> 12 | D25: Fachverantwortung: David Steimer
A26: Offene Kantonsregeln | B26: =COUNTIFS('Feiertagsregeln'!$R$7:$R$122,"open") -> 104 | D26: Nächste Jahresprüfung: spätestens 15.11.2027
A29: Pflege: Regeln und Quellen über stabile IDs verknüpfen. Keine Zeilennummer als Identität.
A30: Gebietszuordnungen erfassen Ein- und Ausschlüsse. Ortssuche und Export folgen separat.
A31: Der Stand enthält keine neue juristische Freigabe und verändert keine Installation.
A32: Gebiets- und Zuordnungsänderungen brauchen eine Neugenerierung des Kalenders.
A33: Formeln und Referenzzeilen sind geschützt. Blattschutz ohne Passwort aufhebbar.
A34: TI/GR: vier Sprachspalten befüllt. Acht TI-Namen in RG sind provisorische Produktübersetzungen.
A35: Zusätzliche Sprachen nur in der Arbeitsmappe. App und Laufzeitdaten bleiben unverändert.
A36: V0.8 ergänzt acht RG-Namen. Strukturvertrag 0.4.0. Keine neue Rechts- oder Releasefreigabe.

Sheet Feiertagskalender
A2: Generierter Feiertagskalender
A4: CH/BE/AG unverändert. TI: 15 offizielle Tage. GR: kantonale Grundliste, keine lokalen Ruhetage. Fristwirkung gesondert prüfen.
A6: Datum | B6: Wochentag | C6: Gemeinwesen | D6: Geltungsbereich | E6: Feiertag | F6: Französisch | G6: Italienisch | H6: Rumantsch Grischun | I6: Rechtskategorie | J6: Fachstatus | K6: Regel-ID | L6: Quellen-ID | M6: Fundstelle | N6: Abdeckung
A7: =INDEX('Feiertagsregeln'!$X$7:$X$96,MATCH($K7,'Feiertagsregeln'!$A$7:$A$96,0)) -> 46600 | B7: =IF(ISNUMBER(A7),CHOOSE(WEEKDAY(A7,2),"Montag","Dienstag","Mittwoch","Donnerstag","Freitag","Samstag","Sonntag"),"n.a.") -> Sonntag | C7: CH | D7: Bundesgebiet | E7: =INDEX('Feiertagsregeln'!$D$7:$D$96,MATCH($K7,'Feiertagsregeln'!$A$7:$A$96,0)) -> Bundesfeiertag | F7: =INDEX('Feiertagsregeln'!$E$7:$E$96,MATCH($K7,'Feiertagsregeln'!$A$7:$A$96,0)) -> Fête nationale | G7: =IF(INDEX('Feiertagsregeln'!$F$7:$F$96,MATCH($K7,'Feiertagsregeln'!$A$7:$A$96,0))="","Noch zu erfassen",INDEX('Feiertagsregeln'!$F$7:$F$96,MATCH($K7,'Feiertagsregeln'!$A$7:$A$96,0))) -> Noch zu erfassen | H7: =IF(INDEX('Feiertagsregeln'!$G$7:$G$96,MATCH($K7,'Feiertagsregeln'!$A$7:$A$96,0))="","Noch zu erfassen",INDEX('Feiertagsregeln'!$G$7:$G$96,MATCH($K7,'Feiertagsregeln'!$A$7:$A$96,0))) -> Noch zu erfassen | I7: =INDEX('Feiertagsregeln'!$H$7:$H$96,MATCH($K7,'Feiertagsregeln'!$A$7:$A$96,0)) -> publicHoliday | J7: =INDEX('Feiertagsregeln'!$R$7:$R$96,MATCH($K7,'Feiertagsregeln'!$A$7:$A$96,0)) -> approved | K7: CH-CAL-HOL-NATIONAL-DAY | L7: =INDEX('Feiertagsregeln'!$Y$7:$Y$96,MATCH($K7,'Feiertagsregeln'!$A$7:$A$96,0)) -> SRC-BUNDESFEIERTAG-19940701 | M7: =INDEX('Feiertagsregeln'!$Z$7:$Z$96,MATCH($K7,'Feiertagsregeln'!$A$7:$A$96,0)) -> Art. 1 | N7: Nur Bundesfeiertag
A8: =INDEX('Feiertagsregeln'!$X$7:$X$96,MATCH($K8,'Feiertagsregeln'!$A$7:$A$96,0)) -> 46600 | B8: =IF(ISNUMBER(A8),CHOOSE(WEEKDAY(A8,2),"Montag","Dienstag","Mittwoch","Donnerstag","Freitag","Samstag","Sonntag"),"n.a.") -> Sonntag | C8: CH-BE | D8: Kanton Bern | E8: =INDEX('Feiertagsregeln'!$D$7:$D$96,MATCH($K8,'Feiertagsregeln'!$A$7:$A$96,0)) -> Bundesfeiertag | F8: =INDEX('Feiertagsregeln'!$E$7:$E$96,MATCH($K8,'Feiertagsregeln'!$A$7:$A$96,0)) -> Fête nationale | G8: =IF(INDEX('Feiertagsregeln'!$F$7:$F$96,MATCH($K8,'Feiertagsregeln'!$A$7:$A$96,0))="","Noch zu erfassen",INDEX('Feiertagsregeln'!$F$7:$F$96,MATCH($K8,'Feiertagsregeln'!$A$7:$A$96,0))) -> Noch zu erfassen | H8: =IF(INDEX('Feiertagsregeln'!$G$7:$G$96,MATCH($K8,'Feiertagsregeln'!$A$7:$A$96,0))="","Noch zu erfassen",INDEX('Feiertagsregeln'!$G$7:$G$96,MATCH($K8,'Feiertagsregeln'!$A$7:$A$96,0))) -> Noch zu erfassen | I8: =INDEX('Feiertagsregeln'!$H$7:$H$96,MATCH($K8,'Feiertagsregeln'!$A$7:$A$96,0)) -> publicHoliday | J8: =INDEX('Feiertagsregeln'!$R$7:$R$96,MATCH($K8,'Feiertagsregeln'!$A$7:$A$96,0)) -> approved | K8: CH-CAL-HOL-NATIONAL-DAY | L8: =INDEX('Feiertagsregeln'!$Y$7:$Y$96,MATCH($K8,'Feiertagsregeln'!$A$7:$A$96,0)) -> SRC-BUNDESFEIERTAG-19940701 | M8: =INDEX('Feiertagsregeln'!$Z$7:$Z$96,MATCH($K8,'Feiertagsregeln'!$A$7:$A$96,0)) -> Art. 1 | N8: Referenzbestand
A9: =INDEX('Feiertagsregeln'!$X$7:$X$96,MATCH($K9,'Feiertagsregeln'!$A$7:$A$96,0)) -> 46388 | B9: =IF(ISNUMBER(A9),CHOOSE(WEEKDAY(A9,2),"Montag","Dienstag","Mittwoch","Donnerstag","Freitag","Samstag","Sonntag"),"n.a.") -> Freitag | C9: CH-BE | D9: Kanton Bern | E9: =INDEX('Feiertagsregeln'!$D$7:$D$96,MATCH($K9,'Feiertagsregeln'!$A$7:$A$96,0)) -> Neujahr | F9: =INDEX('Feiertagsregeln'!$E$7:$E$96,MATCH($K9,'Feiertagsregeln'!$A$7:$A$96,0)) -> Nouvel An | G9: =IF(INDEX('Feiertagsregeln'!$F$7:$F$96,MATCH($K9,'Feiertagsregeln'!$A$7:$A$96,0))="","Noch zu erfassen",INDEX('Feiertagsregeln'!$F$7:$F$96,MATCH($K9,'Feiertagsregeln'!$A$7:$A$96,0))) -> Noch zu erfassen | H9: =IF(INDEX('Feiertagsregeln'!$G$7:$G$96,MATCH($K9,'Feiertagsregeln'!$A$7:$A$96,0))="","Noch zu erfassen",INDEX('Feiertagsregeln'!$G$7:$G$96,MATCH($K9,'Feiertagsregeln'!$A$7:$A$96,0))) -> Noch zu erfassen | I9: =INDEX('Feiertagsregeln'!$H$7:$H$96,MATCH($K9,'Feiertagsregeln'!$A$7:$A$96,0)) -> publicHoliday | J9: =INDEX('Feiertagsregeln'!$R$7:$R$96,MATCH($K9,'Feiertagsregeln'!$A$7:$A$96,0)) -> approved | K9: BE-CAL-HOL-NEW-YEAR | L9: =INDEX('Feiertagsregeln'!$Y$7:$Y$96,MATCH($K9,'Feiertagsregeln'!$A$7:$A$96,0)) -> SRC-FRG-BE-20210401 | M9: =INDEX('Feiertagsregeln'!$Z$7:$Z$96,MATCH($K9,'Feiertagsregeln'!$A$7:$A$96,0)) -> Art. 2 Abs. 1 Bst. c | N9: Referenzbestand
A10: =INDEX('Feiertagsregeln'!$X$7:$X$96,MATCH($K10,'Feiertagsregeln'!$A$7:$A$96,0)) -> 46389 | B10: =IF(ISNUMBER(A10),CHOOSE(WEEKDAY(A10,2),"Montag","Dienstag","Mittwoch","Donnerstag","Freitag","Samstag","Sonntag"),"n.a.") -> Samstag | C10: CH-BE | D10: Kanton Bern | E10: =INDEX('Feiertagsregeln'!$D$7:$D$96,MATCH($K10,'Feiertagsregeln'!$A$7:$A$96,0)) -> Berchtoldstag | F10: =INDEX('Feiertagsregeln'!$E$7:$E$96,MATCH($K10,'Feiertagsregeln'!$A$7:$A$96,0)) -> Saint-Berchtold | G10: =IF(INDEX('Feiertagsregeln'!$F$7:$F$96,MATCH($K10,'Feiertagsregeln'!$A$7:$A$96,0))="","Noch zu erfassen",INDEX('Feiertagsregeln'!$F$7:$F$96,MATCH($K10,'Feiertagsregeln'!$A$7:$A$96,0))) -> Noch zu erfassen | H10: =IF(INDEX('Feiertagsregeln'!$G$7:$G$96,MATCH($K10,'Feiertagsregeln'!$A$7:$A$96,0))="","Noch zu erfassen",INDEX('Feiertagsregeln'!$G$7:$G$96,MATCH($K10,'Feiertagsregeln'!$A$7:$A$96,0))) -> Noch zu erfassen | I10: =INDEX('Feiertagsregeln'!$H$7:$H$96,MATCH($K10,'Feiertagsregeln'!$A$7:$A$96,0)) -> publicHoliday | J10: =INDEX('Feiertagsregeln'!$R$7:$R$96,MATCH($K10,'Feiertagsregeln'!$A$7:$A$96,0)) -> approved | K10: BE-CAL-HOL-BERCHTOLD-DAY | L10: =INDEX('Feiertagsregeln'!$Y$7:$Y$96,MATCH($K10,'Feiertagsregeln'!$A$7:$A$96,0)) -> SRC-FRG-BE-20210401 | M10: =INDEX('Feiertagsregeln'!$Z$7:$Z$96,MATCH($K10,'Feiertagsregeln'!$A$7:$A$96,0)) -> Art. 2 Abs. 1 Bst. c | N10: Referenzbestand
A11: =INDEX('Feiertagsregeln'!$X$7:$X$96,MATCH($K11,'Feiertagsregeln'!$A$7:$A$96,0)) -> 46472 | B11: =IF(ISNUMBER(A11),CHOOSE(WEEKDAY(A11,2),"Montag","Dienstag","Mittwoch","Donnerstag","Freitag","Samstag","Sonntag"),"n.a.") -> Freitag | C11: CH-BE | D11: Kanton Bern | E11: =INDEX('Feiertagsregeln'!$D$7:$D$96,MATCH($K11,'Feiertagsregeln'!$A$7:$A$96,0)) -> Karfreitag | F11: =INDEX('Feiertagsregeln'!$E$7:$E$96,MATCH($K11,'Feiertagsregeln'!$A$7:$A$96,0)) -> Vendredi saint | G11: =IF(INDEX('Feiertagsregeln'!$F$7:$F$96,MATCH($K11,'Feiertagsregeln'!$A$7:$A$96,0))="","Noch zu erfassen",INDEX('Feiertagsregeln'!$F$7:$F$96,MATCH($K11,'Feiertagsregeln'!$A$7:$A$96,0))) -> Noch zu erfassen | H11: =IF(INDEX('Feiertagsregeln'!$G$7:$G$96,MATCH($K11,'Feiertagsregeln'!$A$7:$A$96,0))="","Noch zu erfassen",INDEX('Feiertagsregeln'!$G$7:$G$96,MATCH($K11,'Feiertagsregeln'!$A$7:$A$96,0))) -> Noch zu erfassen | I11: =INDEX('Feiertagsregeln'!$H$7:$H$96,MATCH($K11,'Feiertagsregeln'!$A$7:$A$96,0)) -> publicHoliday | J11: =INDEX('Feiertagsregeln'!$R$7:$R$96,MATCH($K11,'Feiertagsregeln'!$A$7:$A$96,0)) -> approved | K11: BE-CAL-HOL-GOOD-FRIDAY | L11: =INDEX('Feiertagsregeln'!$Y$7:$Y$96,MATCH($K11,'Feiertagsregeln'!$A$7:$A$96,0)) -> SRC-FRG-BE-20210401 | M11: =INDEX('Feiertagsregeln'!$Z$7:$Z$96,MATCH($K11,'Feiertagsregeln'!$A$7:$A$96,0)) -> Art. 2 Abs. 1 Bst. b | N11: Referenzbestand
A12: =INDEX('Feiertagsregeln'!$X$7:$X$96,MATCH($K12,'Feiertagsregeln'!$A$7:$A$96,0)) -> 46474 | B12: =IF(ISNUMBER(A12),CHOOSE(WEEKDAY(A12,2),"Montag","Dienstag","Mittwoch","Donnerstag","Freitag","Samstag","Sonntag"),"n.a.") -> Sonntag | C12: CH-BE | D12: Kanton Bern | E12: =INDEX('Feiertagsregeln'!$D$7:$D$96,MATCH($K12,'Feiertagsregeln'!$A$7:$A$96,0)) -> Ostern | F12: =INDEX('Feiertagsregeln'!$E$7:$E$96,MATCH($K12,'Feiertagsregeln'!$A$7:$A$96,0)) -> Pâques | G12: =IF(INDEX('Feiertagsregeln'!$F$7:$F$96,MATCH($K12,'Feiertagsregeln'!$A$7:$A$96,0))="","Noch zu erfassen",INDEX('Feiertagsregeln'!$F$7:$F$96,MATCH($K12,'Feiertagsregeln'!$A$7:$A$96,0))) -> Noch zu erfassen | H12: =IF(INDEX('Feiertagsregeln'!$G$7:$G$96,MATCH($K12,'Feiertagsregeln'!$A$7:$A$96,0))="","Noch zu erfassen",INDEX('Feiertagsregeln'!$G$7:$G$96,MATCH($K12,'Feiertagsregeln'!$A$7:$A$96,0))) -> Noch zu erfassen | I12: =INDEX('Feiertagsregeln'!$H$7:$H$96,MATCH($K12,'Feiertagsregeln'!$A$7:$A$96,0)) -> publicHoliday | J12: =INDEX('Feiertagsregeln'!$R$7:$R$96,MATCH($K12,'Feiertagsregeln'!$A$7:$A$96,0)) -> approved | K12: BE-CAL-HOL-EASTER | L12: =INDEX('Feiertagsregeln'!$Y$7:$Y$96,MATCH($K12,'Feiertagsregeln'!$A$7:$A$96,0)) -> SRC-FRG-BE-20210401 | M12: =INDEX('Feiertagsregeln'!$Z$7:$Z$96,MATCH($K12,'Feiertagsregeln'!$A$7:$A$96,0)) -> Art. 2 Abs. 1 Bst. b | N12: Referenzbestand
A13: =INDEX('Feiertagsregeln'!$X$7:$X$96,MATCH($K13,'Feiertagsregeln'!$A$7:$A$96,0)) -> 46475 | B13: =IF(ISNUMBER(A13),CHOOSE(WEEKDAY(A13,2),"Montag","Dienstag","Mittwoch","Donnerstag","Freitag","Samstag","Sonntag"),"n.a.") -> Montag | C13: CH-BE | D13: Kanton Bern | E13: =INDEX('Feiertagsregeln'!$D$7:$D$96,MATCH($K13,'Feiertagsregeln'!$A$7:$A$96,0)) -> Ostermontag | F13: =INDEX('Feiertagsregeln'!$E$7:$E$96,MATCH($K13,'Feiertagsregeln'!$A$7:$A$96,0)) -> Lundi de Pâques | G13: =IF(INDEX('Feiertagsregeln'!$F$7:$F$96,MATCH($K13,'Feiertagsregeln'!$A$7:$A$96,0))="","Noch zu erfassen",INDEX('Feiertagsregeln'!$F$7:$F$96,MATCH($K13,'Feiertagsregeln'!$A$7:$A$96,0))) -> Noch zu erfassen | H13: =IF(INDEX('Feiertagsregeln'!$G$7:$G$96,MATCH($K13,'Feiertagsregeln'!$A$7:$A$96,0))="","Noch zu erfassen",INDEX('Feiertagsregeln'!$G$7:$G$96,MATCH($K13,'Feiertagsregeln'!$A$7:$A$96,0))) -> Noch zu erfassen | I13: =INDEX('Feiertagsregeln'!$H$7:$H$96,MATCH($K13,'Feiertagsregeln'!$A$7:$A$96,0)) -> publicHoliday | J13: =INDEX('Feiertagsregeln'!$R$7:$R$96,MATCH($K13,'Feiertagsregeln'!$A$7:$A$96,0)) -> approved | K13: BE-CAL-HOL-EASTER-MONDAY | L13: =INDEX('Feiertagsregeln'!$Y$7:$Y$96,MATCH($K13,'Feiertagsregeln'!$A$7:$A$96,0)) -> SRC-FRG-BE-20210401 | M13: =INDEX('Feiertagsregeln'!$Z$7:$Z$96,MATCH($K13,'Feiertagsregeln'!$A$7:$A$96,0)) -> Art. 2 Abs. 1 Bst. c | N13: Referenzbestand
A14: =INDEX('Feiertagsregeln'!$X$7:$X$96,MATCH($K14,'Feiertagsregeln'!$A$7:$A$96,0)) -> 46513 | B14: =IF(ISNUMBER(A14),CHOOSE(WEEKDAY(A14,2),"Montag","Dienstag","Mittwoch","Donnerstag","Freitag","Samstag","Sonntag"),"n.a.") -> Donnerstag | C14: CH-BE | D14: Kanton Bern | E14: =INDEX('Feiertagsregeln'!$D$7:$D$96,MATCH($K14,'Feiertagsregeln'!$A$7:$A$96,0)) -> Auffahrt | F14: =INDEX('Feiertagsregeln'!$E$7:$E$96,MATCH($K14,'Feiertagsregeln'!$A$7:$A$96,0)) -> Ascension | G14: =IF(INDEX('Feiertagsregeln'!$F$7:$F$96,MATCH($K14,'Feiertagsregeln'!$A$7:$A$96,0))="","Noch zu erfassen",INDEX('Feiertagsregeln'!$F$7:$F$96,MATCH($K14,'Feiertagsregeln'!$A$7:$A$96,0))) -> Noch zu erfassen | H14: =IF(INDEX('Feiertagsregeln'!$G$7:$G$96,MATCH($K14,'Feiertagsregeln'!$A$7:$A$96,0))="","Noch zu erfassen",INDEX('Feiertagsregeln'!$G$7:$G$96,MATCH($K14,'Feiertagsregeln'!$A$7:$A$96,0))) -> Noch zu erfassen | I14: =INDEX('Feiertagsregeln'!$H$7:$H$96,MATCH($K14,'Feiertagsregeln'!$A$7:$A$96,0)) -> publicHoliday | J14: =INDEX('Feiertagsregeln'!$R$7:$R$96,MATCH($K14,'Feiertagsregeln'!$A$7:$A$96,0)) -> approved | K14: BE-CAL-HOL-ASCENSION | L14: =INDEX('Feiertagsregeln'!$Y$7:$Y$96,MATCH($K14,'Feiertagsregeln'!$A$7:$A$96,0)) -> SRC-FRG-BE-20210401 | M14: =INDEX('Feiertagsregeln'!$Z$7:$Z$96,MATCH($K14,'Feiertagsregeln'!$A$7:$A$96,0)) -> Art. 2 Abs. 1 Bst. b | N14: Referenzbestand
A15: =INDEX('Feiertagsregeln'!$X$7:$X$96,MATCH($K15,'Feiertagsregeln'!$A$7:$A$96,0)) -> 46523 | B15: =IF(ISNUMBER(A15),CHOOSE(WEEKDAY(A15,2),"Montag","Dienstag","Mittwoch","Donnerstag","Freitag","Samstag","Sonntag"),"n.a.") -> Sonntag | C15: CH-BE | D15: Kanton Bern | E15: =INDEX('Feiertagsregeln'!$D$7:$D$96,MATCH($K15,'Feiertagsregeln'!$A$7:$A$96,0)) -> Pfingsten | F15: =INDEX('Feiertagsregeln'!$E$7:$E$96,MATCH($K15,'Feiertagsregeln'!$A$7:$A$96,0)) -> Pentecôte | G15: =IF(INDEX('Feiertagsregeln'!$F$7:$F$96,MATCH($K15,'Feiertagsregeln'!$A$7:$A$96,0))="","Noch zu erfassen",INDEX('Feiertagsregeln'!$F$7:$F$96,MATCH($K15,'Feiertagsregeln'!$A$7:$A$96,0))) -> Noch zu erfassen | H15: =IF(INDEX('Feiertagsregeln'!$G$7:$G$96,MATCH($K15,'Feiertagsregeln'!$A$7:$A$96,0))="","Noch zu erfassen",INDEX('Feiertagsregeln'!$G$7:$G$96,MATCH($K15,'Feiertagsregeln'!$A$7:$A$96,0))) -> Noch zu erfassen | I15: =INDEX('Feiertagsregeln'!$H$7:$H$96,MATCH($K15,'Feiertagsregeln'!$A$7:$A$96,0)) -> publicHoliday | J15: =INDEX('Feiertagsregeln'!$R$7:$R$96,MATCH($K15,'Feiertagsregeln'!$A$7:$A$96,0)) -> approved | K15: BE-CAL-HOL-PENTECOST | L15: =INDEX('Feiertagsregeln'!$Y$7:$Y$96,MATCH($K15,'Feiertagsregeln'!$A$7:$A$96,0)) -> SRC-FRG-BE-20210401 | M15: =INDEX('Feiertagsregeln'!$Z$7:$Z$96,MATCH($K15,'Feiertagsregeln'!$A$7:$A$96,0)) -> Art. 2 Abs. 1 Bst. b | N15: Referenzbestand
A16: =INDEX('Feiertagsregeln'!$X$7:$X$96,MATCH($K16,'Feiertagsregeln'!$A$7:$A$96,0)) -> 46524 | B16: =IF(ISNUMBER(A16),CHOOSE(WEEKDAY(A16,2),"Montag","Dienstag","Mittwoch","Donnerstag","Freitag","Samstag","Sonntag"),"n.a.") -> Montag | C16: CH-BE | D16: Kanton Bern | E16: =INDEX('Feiertagsregeln'!$D$7:$D$96,MATCH($K16,'Feiertagsregeln'!$A$7:$A$96,0)) -> Pfingstmontag | F16: =INDEX('Feiertagsregeln'!$E$7:$E$96,MATCH($K16,'Feiertagsregeln'!$A$7:$A$96,0)) -> Lundi de Pentecôte | G16: =IF(INDEX('Feiertagsregeln'!$F$7:$F$96,MATCH($K16,'Feiertagsregeln'!$A$7:$A$96,0))="","Noch zu erfassen",INDEX('Feiertagsregeln'!$F$7:$F$96,MATCH($K16,'Feiertagsregeln'!$A$7:$A$96,0))) -> Noch zu erfassen | H16: =IF(INDEX('Feiertagsregeln'!$G$7:$G$96,MATCH($K16,'Feiertagsregeln'!$A$7:$A$96,0))="","Noch zu erfassen",INDEX('Feiertagsregeln'!$G$7:$G$96,MATCH($K16,'Feiertagsregeln'!$A$7:$A$96,0))) -> Noch zu erfassen | I16: =INDEX('Feiertagsregeln'!$H$7:$H$96,MATCH($K16,'Feiertagsregeln'!$A$7:$A$96,0)) -> publicHoliday | J16: =INDEX('Feiertagsregeln'!$R$7:$R$96,MATCH($K16,'Feiertagsregeln'!$A$7:$A$96,0)) -> approved | K16: BE-CAL-HOL-WHIT-MONDAY | L16: =INDEX('Feiertagsregeln'!$Y$7:$Y$96,MATCH($K16,'Feiertagsregeln'!$A$7:$A$96,0)) -> SRC-FRG-BE-20210401 | M16: =INDEX('Feiertagsregeln'!$Z$7:$Z$96,MATCH($K16,'Feiertagsregeln'!$A$7:$A$96,0)) -> Art. 2 Abs. 1 Bst. c | N16: Referenzbestand
A17: =INDEX('Feiertagsregeln'!$X$7:$X$96,MATCH($K17,'Feiertagsregeln'!$A$7:$A$96,0)) -> 46649 | B17: =IF(ISNUMBER(A17),CHOOSE(WEEKDAY(A17,2),"Montag","Dienstag","Mittwoch","Donnerstag","Freitag","Samstag","Sonntag"),"n.a.") -> Sonntag | C17: CH-BE | D17: Kanton Bern | E17: =INDEX('Feiertagsregeln'!$D$7:$D$96,MATCH($K17,'Feiertagsregeln'!$A$7:$A$96,0)) -> Eidgenössischer Dank-, Buss- und Bettag | F17: =INDEX('Feiertagsregeln'!$E$7:$E$96,MATCH($K17,'Feiertagsregeln'!$A$7:$A$96,0)) -> Jeûne fédéral | G17: =IF(INDEX('Feiertagsregeln'!$F$7:$F$96,MATCH($K17,'Feiertagsregeln'!$A$7:$A$96,0))="","Noch zu erfassen",INDEX('Feiertagsregeln'!$F$7:$F$96,MATCH($K17,'Feiertagsregeln'!$A$7:$A$96,0))) -> Noch zu erfassen | H17: =IF(INDEX('Feiertagsregeln'!$G$7:$G$96,MATCH($K17,'Feiertagsregeln'!$A$7:$A$96,0))="","Noch zu erfassen",INDEX('Feiertagsregeln'!$G$7:$G$96,MATCH($K17,'Feiertagsregeln'!$A$7:$A$96,0))) -> Noch zu erfassen | I17: =INDEX('Feiertagsregeln'!$H$7:$H$96,MATCH($K17,'Feiertagsregeln'!$A$7:$A$96,0)) -> publicHoliday | J17: =INDEX('Feiertagsregeln'!$R$7:$R$96,MATCH($K17,'Feiertagsregeln'!$A$7:$A$96,0)) -> approved | K17: BE-CAL-HOL-FEDERAL-FAST | L17: =INDEX('Feiertagsregeln'!$Y$7:$Y$96,MATCH($K17,'Feiertagsregeln'!$A$7:$A$96,0)) -> SRC-FRG-BE-20210401 | M17: =INDEX('Feiertagsregeln'!$Z$7:$Z$96,MATCH($K17,'Feiertagsregeln'!$A$7:$A$96,0)) -> Art. 2 Abs. 1 Bst. b | N17: Referenzbestand
A18: =INDEX('Feiertagsregeln'!$X$7:$X$96,MATCH($K18,'Feiertagsregeln'!$A$7:$A$96,0)) -> 46746 | B18: =IF(ISNUMBER(A18),CHOOSE(WEEKDAY(A18,2),"Montag","Dienstag","Mittwoch","Donnerstag","Freitag","Samstag","Sonntag"),"n.a.") -> Samstag | C18: CH-BE | D18: Kanton Bern | E18: =INDEX('Feiertagsregeln'!$D$7:$D$96,MATCH($K18,'Feiertagsregeln'!$A$7:$A$96,0)) -> Weihnachten | F18: =INDEX('Feiertagsregeln'!$E$7:$E$96,MATCH($K18,'Feiertagsregeln'!$A$7:$A$96,0)) -> Noël | G18: =IF(INDEX('Feiertagsregeln'!$F$7:$F$96,MATCH($K18,'Feiertagsregeln'!$A$7:$A$96,0))="","Noch zu erfassen",INDEX('Feiertagsregeln'!$F$7:$F$96,MATCH($K18,'Feiertagsregeln'!$A$7:$A$96,0))) -> Noch zu erfassen | H18: =IF(INDEX('Feiertagsregeln'!$G$7:$G$96,MATCH($K18,'Feiertagsregeln'!$A$7:$A$96,0))="","Noch zu erfassen",INDEX('Feiertagsregeln'!$G$7:$G$96,MATCH($K18,'Feiertagsregeln'!$A$7:$A$96,0))) -> Noch zu erfassen | I18: =INDEX('Feiertagsregeln'!$H$7:$H$96,MATCH($K18,'Feiertagsregeln'!$A$7:$A$96,0)) -> publicHoliday | J18: =INDEX('Feiertagsregeln'!$R$7:$R$96,MATCH($K18,'Feiertagsregeln'!$A$7:$A$96,0)) -> approved | K18: BE-CAL-HOL-CHRISTMAS | L18: =INDEX('Feiertagsregeln'!$Y$7:$Y$96,MATCH($K18,'Feiertagsregeln'!$A$7:$A$96,0)) -> SRC-FRG-BE-20210401 | M18: =INDEX('Feiertagsregeln'!$Z$7:$Z$96,MATCH($K18,'Feiertagsregeln'!$A$7:$A$96,0)) -> Art. 2 Abs. 1 Bst. b | N18: Referenzbestand
A19: =INDEX('Feiertagsregeln'!$X$7:$X$96,MATCH($K19,'Feiertagsregeln'!$A$7:$A$96,0)) -> 46747 | B19: =IF(ISNUMBER(A19),CHOOSE(WEEKDAY(A19,2),"Montag","Dienstag","Mittwoch","Donnerstag","Freitag","Samstag","Sonntag"),"n.a.") -> Sonntag | C19: CH-BE | D19: Kanton Bern | E19: =INDEX('Feiertagsregeln'!$D$7:$D$96,MATCH($K19,'Feiertagsregeln'!$A$7:$A$96,0)) -> Stephanstag | F19: =INDEX('Feiertagsregeln'!$E$7:$E$96,MATCH($K19,'Feiertagsregeln'!$A$7:$A$96,0)) -> Saint-Étienne | G19: =IF(INDEX('Feiertagsregeln'!$F$7:$F$96,MATCH($K19,'Feiertagsregeln'!$A$7:$A$96,0))="","Noch zu erfassen",INDEX('Feiertagsregeln'!$F$7:$F$96,MATCH($K19,'Feiertagsregeln'!$A$7:$A$96,0))) -> Noch zu erfassen | H19: =IF(INDEX('Feiertagsregeln'!$G$7:$G$96,MATCH($K19,'Feiertagsregeln'!$A$7:$A$96,0))="","Noch zu erfassen",INDEX('Feiertagsregeln'!$G$7:$G$96,MATCH($K19,'Feiertagsregeln'!$A$7:$A$96,0))) -> Noch zu erfassen | I19: =INDEX('Feiertagsregeln'!$H$7:$H$96,MATCH($K19,'Feiertagsregeln'!$A$7:$A$96,0)) -> publicHoliday | J19: =INDEX('Feiertagsregeln'!$R$7:$R$96,MATCH($K19,'Feiertagsregeln'!$A$7:$A$96,0)) -> approved | K19: BE-CAL-HOL-ST-STEPHEN | L19: =INDEX('Feiertagsregeln'!$Y$7:$Y$96,MATCH($K19,'Feiertagsregeln'!$A$7:$A$96,0)) -> SRC-FRG-BE-20210401 | M19: =INDEX('Feiertagsregeln'!$Z$7:$Z$96,MATCH($K19,'Feiertagsregeln'!$A$7:$A$96,0)) -> Art. 2 Abs. 1 Bst. c | N19: Referenzbestand
A20: =INDEX('Feiertagsregeln'!$X$7:$X$96,MATCH($K20,'Feiertagsregeln'!$A$7:$A$96,0)) -> 46534 | B20: =IF(ISNUMBER(A20),CHOOSE(WEEKDAY(A20,2),"Montag","Dienstag","Mittwoch","Donnerstag","Freitag","Samstag","Sonntag"),"n.a.") -> Donnerstag | C20: CH-AG | D20: Bezirk Baden ohne Bergdietikon | E20: =INDEX('Feiertagsregeln'!$D$7:$D$96,MATCH($K20,'Feiertagsregeln'!$A$7:$A$96,0)) -> Fronleichnam | F20: =INDEX('Feiertagsregeln'!$E$7:$E$96,MATCH($K20,'Feiertagsregeln'!$A$7:$A$96,0)) -> Fête-Dieu | G20: =IF(INDEX('Feiertagsregeln'!$F$7:$F$96,MATCH($K20,'Feiertagsregeln'!$A$7:$A$96,0))="","Noch zu erfassen",INDEX('Feiertagsregeln'!$F$7:$F$96,MATCH($K20,'Feiertagsregeln'!$A$7:$A$96,0))) -> Noch zu erfassen | H20: =IF(INDEX('Feiertagsregeln'!$G$7:$G$96,MATCH($K20,'Feiertagsregeln'!$A$7:$A$96,0))="","Noch zu erfassen",INDEX('Feiertagsregeln'!$G$7:$G$96,MATCH($K20,'Feiertagsregeln'!$A$7:$A$96,0))) -> Noch zu erfassen | I20: =INDEX('Feiertagsregeln'!$H$7:$H$96,MATCH($K20,'Feiertagsregeln'!$A$7:$A$96,0)) -> labourLawHoliday | J20: open | K20: AG-WORK-HOL-CORPUS-CHRISTI | L20: =INDEX('Feiertagsregeln'!$Y$7:$Y$96,MATCH($K20,'Feiertagsregeln'!$A$7:$A$96,0)) -> SRC-AG-EGARR-20250901 | M20: =INDEX('Feiertagsregeln'!$Z$7:$Z$96,MATCH($K20,'Feiertagsregeln'!$A$7:$A$96,0)) -> § 6 Abs. 1 Bst. b Ziff. 2 | N20: Normliste erfasst, Fachfreigabe offen
A21: =INDEX('Feiertagsregeln'!$X$7:$X$96,MATCH($K21,'Feiertagsregeln'!$A$7:$A$96,0)) -> 46389 | B21: =IF(ISNUMBER(A21),CHOOSE(WEEKDAY(A21,2),"Montag","Dienstag","Mittwoch","Donnerstag","Freitag","Samstag","Sonntag"),"n.a.") -> Samstag | C21: CH-AG | D21: Gemeinde Bergdietikon | E21: =INDEX('Feiertagsregeln'!$D$7:$D$96,MATCH($K21,'Feiertagsregeln'!$A$7:$A$96,0)) -> Berchtoldstag | F21: =INDEX('Feiertagsregeln'!$E$7:$E$96,MATCH($K21,'Feiertagsregeln'!$A$7:$A$96,0)) -> Saint-Berchtold | G21: =IF(INDEX('Feiertagsregeln'!$F$7:$F$96,MATCH($K21,'Feiertagsregeln'!$A$7:$A$96,0))="","Noch zu erfassen",INDEX('Feiertagsregeln'!$F$7:$F$96,MATCH($K21,'Feiertagsregeln'!$A$7:$A$96,0))) -> Noch zu erfassen | H21: =IF(INDEX('Feiertagsregeln'!$G$7:$G$96,MATCH($K21,'Feiertagsregeln'!$A$7:$A$96,0))="","Noch zu erfassen",INDEX('Feiertagsregeln'!$G$7:$G$96,MATCH($K21,'Feiertagsregeln'!$A$7:$A$96,0))) -> Noch zu erfassen | I21: =INDEX('Feiertagsregeln'!$H$7:$H$96,MATCH($K21,'Feiertagsregeln'!$A$7:$A$96,0)) -> labourLawHoliday | J21: open | K21: AG-WORK-HOL-BERCHTOLD | L21: =INDEX('Feiertagsregeln'!$Y$7:$Y$96,MATCH($K21,'Feiertagsregeln'!$A$7:$A$96,0)) -> SRC-AG-EGARR-20250901 | M21: =INDEX('Feiertagsregeln'!$Z$7:$Z$96,MATCH($K21,'Feiertagsregeln'!$A$7:$A$96,0)) -> § 6 Abs. 1 Bst. b Ziff. 1 | N21: Normliste erfasst, Fachfreigabe offen
A22: =INDEX('Feiertagsregeln'!$X$7:$X$96,MATCH($K22,'Feiertagsregeln'!$A$7:$A$96,0)) -> 46692 | B22: =IF(ISNUMBER(A22),CHOOSE(WEEKDAY(A22,2),"Montag","Dienstag","Mittwoch","Donnerstag","Freitag","Samstag","Sonntag"),"n.a.") -> Montag | C22: CH-AG | D22: Aargau, prozessuale Zuordnung | E22: =INDEX('Feiertagsregeln'!$D$7:$D$96,MATCH($K22,'Feiertagsregeln'!$A$7:$A$96,0)) -> Allerheiligen | F22: =INDEX('Feiertagsregeln'!$E$7:$E$96,MATCH($K22,'Feiertagsregeln'!$A$7:$A$96,0)) -> Toussaint | G22: =IF(INDEX('Feiertagsregeln'!$F$7:$F$96,MATCH($K22,'Feiertagsregeln'!$A$7:$A$96,0))="","Noch zu erfassen",INDEX('Feiertagsregeln'!$F$7:$F$96,MATCH($K22,'Feiertagsregeln'!$A$7:$A$96,0))) -> Noch zu erfassen | H22: =IF(INDEX('Feiertagsregeln'!$G$7:$G$96,MATCH($K22,'Feiertagsregeln'!$A$7:$A$96,0))="","Noch zu erfassen",INDEX('Feiertagsregeln'!$G$7:$G$96,MATCH($K22,'Feiertagsregeln'!$A$7:$A$96,0))) -> Noch zu erfassen | I22: =INDEX('Feiertagsregeln'!$H$7:$H$96,MATCH($K22,'Feiertagsregeln'!$A$7:$A$96,0)) -> proceduralEquivalentDay | J22: open | K22: AG-PROC-DAY-ALL-SAINTS | L22: =INDEX('Feiertagsregeln'!$Y$7:$Y$96,MATCH($K22,'Feiertagsregeln'!$A$7:$A$96,0)) -> SRC-AG-EGZPO | M22: =INDEX('Feiertagsregeln'!$Z$7:$Z$96,MATCH($K22,'Feiertagsregeln'!$A$7:$A$96,0)) -> § 21 | N22: Normliste erfasst, Fachfreigabe offen
A23: =INDEX('Feiertagsregeln'!$X$7:$X$96,MATCH($K23,'Feiertagsregeln'!$A$7:$A$96,0)) -> 46388 | B23: =IF(ISNUMBER(A23),CHOOSE(WEEKDAY(A23,2),"Montag","Dienstag","Mittwoch","Donnerstag","Freitag","Samstag","Sonntag"),"n.a.") -> Freitag | C23: CH-AG | D23: Bezirke Aarau, Brugg, Kulm, Lenzburg und Zofingen | E23: =INDEX('Feiertagsregeln'!$D$7:$D$96,MATCH($K23,'Feiertagsregeln'!$A$7:$A$96,0)) -> Neujahr | F23: =INDEX('Feiertagsregeln'!$E$7:$E$96,MATCH($K23,'Feiertagsregeln'!$A$7:$A$96,0)) -> Nouvel An | G23: =IF(INDEX('Feiertagsregeln'!$F$7:$F$96,MATCH($K23,'Feiertagsregeln'!$A$7:$A$96,0))="","Noch zu erfassen",INDEX('Feiertagsregeln'!$F$7:$F$96,MATCH($K23,'Feiertagsregeln'!$A$7:$A$96,0))) -> Noch zu erfassen | H23: =IF(INDEX('Feiertagsregeln'!$G$7:$G$96,MATCH($K23,'Feiertagsregeln'!$A$7:$A$96,0))="","Noch zu erfassen",INDEX('Feiertagsregeln'!$G$7:$G$96,MATCH($K23,'Feiertagsregeln'!$A$7:$A$96,0))) -> Noch zu erfassen | I23: =INDEX('Feiertagsregeln'!$H$7:$H$96,MATCH($K23,'Feiertagsregeln'!$A$7:$A$96,0)) -> labourLawHoliday | J23: open | K23: AG-WORK-HOL-A-NEW-YEAR | L23: =INDEX('Feiertagsregeln'!$Y$7:$Y$96,MATCH($K23,'Feiertagsregeln'!$A$7:$A$96,0)) -> SRC-AG-EGARR-20250901 | M23: =INDEX('Feiertagsregeln'!$Z$7:$Z$96,MATCH($K23,'Feiertagsregeln'!$A$7:$A$96,0)) -> § 6 Abs. 1 Bst. a | N23: Normliste erfasst, Fachfreigabe offen
A24: =INDEX('Feiertagsregeln'!$X$7:$X$96,MATCH($K24,'Feiertagsregeln'!$A$7:$A$96,0)) -> 46389 | B24: =IF(ISNUMBER(A24),CHOOSE(WEEKDAY(A24,2),"Montag","Dienstag","Mittwoch","Donnerstag","Freitag","Samstag","Sonntag"),"n.a.") -> Samstag | C24: CH-AG | D24: Bezirke Aarau, Brugg, Kulm, Lenzburg und Zofingen | E24: =INDEX('Feiertagsregeln'!$D$7:$D$96,MATCH($K24,'Feiertagsregeln'!$A$7:$A$96,0)) -> Berchtoldstag | F24: =INDEX('Feiertagsregeln'!$E$7:$E$96,MATCH($K24,'Feiertagsregeln'!$A$7:$A$96,0)) -> Saint-Berchtold | G24: =IF(INDEX('Feiertagsregeln'!$F$7:$F$96,MATCH($K24,'Feiertagsregeln'!$A$7:$A$96,0))="","Noch zu erfassen",INDEX('Feiertagsregeln'!$F$7:$F$96,MATCH($K24,'Feiertagsregeln'!$A$7:$A$96,0))) -> Noch zu erfassen | H24: =IF(INDEX('Feiertagsregeln'!$G$7:$G$96,MATCH($K24,'Feiertagsregeln'!$A$7:$A$96,0))="","Noch zu erfassen",INDEX('Feiertagsregeln'!$G$7:$G$96,MATCH($K24,'Feiertagsregeln'!$A$7:$A$96,0))) -> Noch zu erfassen | I24: =INDEX('Feiertagsregeln'!$H$7:$H$96,MATCH($K24,'Feiertagsregeln'!$A$7:$A$96,0)) -> labourLawHoliday | J24: open | K24: AG-WORK-HOL-A-BERCHTOLD | L24: =INDEX('Feiertagsregeln'!$Y$7:$Y$96,MATCH($K24,'Feiertagsregeln'!$A$7:$A$96,0)) -> SRC-AG-EGARR-20250901 | M24: =INDEX('Feiertagsregeln'!$Z$7:$Z$96,MATCH($K24,'Feiertagsregeln'!$A$7:$A$96,0)) -> § 6 Abs. 1 Bst. a | N24: Normliste erfasst, Fachfreigabe offen
A25: =INDEX('Feiertagsregeln'!$X$7:$X$96,MATCH($K25,'Feiertagsregeln'!$A$7:$A$96,0)) -> 46472 | B25: =IF(ISNUMBER(A25),CHOOSE(WEEKDAY(A25,2),"Montag","Dienstag","Mittwoch","Donnerstag","Freitag","Samstag","Sonntag"),"n.a.") -> Freitag | C25: CH-AG | D25: Bezirke Aarau, Brugg, Kulm, Lenzburg und Zofingen | E25: =INDEX('Feiertagsregeln'!$D$7:$D$96,MATCH($K25,'Feiertagsregeln'!$A$7:$A$96,0)) -> Karfreitag | F25: =INDEX('Feiertagsregeln'!$E$7:$E$96,MATCH($K25,'Feiertagsregeln'!$A$7:$A$96,0)) -> Vendredi saint | G25: =IF(INDEX('Feiertagsregeln'!$F$7:$F$96,MATCH($K25,'Feiertagsregeln'!$A$7:$A$96,0))="","Noch zu erfassen",INDEX('Feiertagsregeln'!$F$7:$F$96,MATCH($K25,'Feiertagsregeln'!$A$7:$A$96,0))) -> Noch zu erfassen | H25: =IF(INDEX('Feiertagsregeln'!$G$7:$G$96,MATCH($K25,'Feiertagsregeln'!$A$7:$A$96,0))="","Noch zu erfassen",INDEX('Feiertagsregeln'!$G$7:$G$96,MATCH($K25,'Feiertagsregeln'!$A$7:$A$96,0))) -> Noch zu erfassen | I25: =INDEX('Feiertagsregeln'!$H$7:$H$96,MATCH($K25,'Feiertagsregeln'!$A$7:$A$96,0)) -> labourLawHoliday | J25: open | K25: AG-WORK-HOL-A-GOOD-FRIDAY | L25: =INDEX('Feiertagsregeln'!$Y$7:$Y$96,MATCH($K25,'Feiertagsregeln'!$A$7:$A$96,0)) -> SRC-AG-EGARR-20250901 | M25: =INDEX('Feiertagsregeln'!$Z$7:$Z$96,MATCH($K25,'Feiertagsregeln'!$A$7:$A$96,0)) -> § 6 Abs. 1 Bst. a | N25: Normliste erfasst, Fachfreigabe offen
A26: =INDEX('Feiertagsregeln'!$X$7:$X$96,MATCH($K26,'Feiertagsregeln'!$A$7:$A$96,0)) -> 46475 | B26: =IF(ISNUMBER(A26),CHOOSE(WEEKDAY(A26,2),"Montag","Dienstag","Mittwoch","Donnerstag","Freitag","Samstag","Sonntag"),"n.a.") -> Montag | C26: CH-AG | D26: Bezirke Aarau, Brugg, Kulm, Lenzburg und Zofingen | E26: =INDEX('Feiertagsregeln'!$D$7:$D$96,MATCH($K26,'Feiertagsregeln'!$A$7:$A$96,0)) -> Ostermontag | F26: =INDEX('Feiertagsregeln'!$E$7:$E$96,MATCH($K26,'Feiertagsregeln'!$A$7:$A$96,0)) -> Lundi de Pâques | G26: =IF(INDEX('Feiertagsregeln'!$F$7:$F$96,MATCH($K26,'Feiertagsregeln'!$A$7:$A$96,0))="","Noch zu erfassen",INDEX('Feiertagsregeln'!$F$7:$F$96,MATCH($K26,'Feiertagsregeln'!$A$7:$A$96,0))) -> Noch zu erfassen | H26: =IF(INDEX('Feiertagsregeln'!$G$7:$G$96,MATCH($K26,'Feiertagsregeln'!$A$7:$A$96,0))="","Noch zu erfassen",INDEX('Feiertagsregeln'!$G$7:$G$96,MATCH($K26,'Feiertagsregeln'!$A$7:$A$96,0))) -> Noch zu erfassen | I26: =INDEX('Feiertagsregeln'!$H$7:$H$96,MATCH($K26,'Feiertagsregeln'!$A$7:$A$96,0)) -> labourLawHoliday | J26: open | K26: AG-WORK-HOL-A-EASTER-MONDAY | L26: =INDEX('Feiertagsregeln'!$Y$7:$Y$96,MATCH($K26,'Feiertagsregeln'!$A$7:$A$96,0)) -> SRC-AG-EGARR-20250901 | M26: =INDEX('Feiertagsregeln'!$Z$7:$Z$96,MATCH($K26,'Feiertagsregeln'!$A$7:$A$96,0)) -> § 6 Abs. 1 Bst. a | N26: Normliste erfasst, Fachfreigabe offen
A27: =INDEX('Feiertagsregeln'!$X$7:$X$96,MATCH($K27,'Feiertagsregeln'!$A$7:$A$96,0)) -> 46513 | B27: =IF(ISNUMBER(A27),CHOOSE(WEEKDAY(A27,2),"Montag","Dienstag","Mittwoch","Donnerstag","Freitag","Samstag","Sonntag"),"n.a.") -> Donnerstag | C27: CH-AG | D27: Bezirke Aarau, Brugg, Kulm, Lenzburg und Zofingen | E27: =INDEX('Feiertagsregeln'!$D$7:$D$96,MATCH($K27,'Feiertagsregeln'!$A$7:$A$96,0)) -> Auffahrt | F27: =INDEX('Feiertagsregeln'!$E$7:$E$96,MATCH($K27,'Feiertagsregeln'!$A$7:$A$96,0)) -> Ascension | G27: =IF(INDEX('Feiertagsregeln'!$F$7:$F$96,MATCH($K27,'Feiertagsregeln'!$A$7:$A$96,0))="","Noch zu erfassen",INDEX('Feiertagsregeln'!$F$7:$F$96,MATCH($K27,'Feiertagsregeln'!$A$7:$A$96,0))) -> Noch zu erfassen | H27: =IF(INDEX('Feiertagsregeln'!$G$7:$G$96,MATCH($K27,'Feiertagsregeln'!$A$7:$A$96,0))="","Noch zu erfassen",INDEX('Feiertagsregeln'!$G$7:$G$96,MATCH($K27,'Feiertagsregeln'!$A$7:$A$96,0))) -> Noch zu erfassen | I27: =INDEX('Feiertagsregeln'!$H$7:$H$96,MATCH($K27,'Feiertagsregeln'!$A$7:$A$96,0)) -> labourLawHoliday | J27: open | K27: AG-WORK-HOL-A-ASCENSION | L27: =INDEX('Feiertagsregeln'!$Y$7:$Y$96,MATCH($K27,'Feiertagsregeln'!$A$7:$A$96,0)) -> SRC-AG-EGARR-20250901 | M27: =INDEX('Feiertagsregeln'!$Z$7:$Z$96,MATCH($K27,'Feiertagsregeln'!$A$7:$A$96,0)) -> § 6 Abs. 1 Bst. a | N27: Normliste erfasst, Fachfreigabe offen
A28: =INDEX('Feiertagsregeln'!$X$7:$X$96,MATCH($K28,'Feiertagsregeln'!$A$7:$A$96,0)) -> 46524 | B28: =IF(ISNUMBER(A28),CHOOSE(WEEKDAY(A28,2),"Montag","Dienstag","Mittwoch","Donnerstag","Freitag","Samstag","Sonntag"),"n.a.") -> Montag | C28: CH-AG | D28: Bezirke Aarau, Brugg, Kulm, Lenzburg und Zofingen | E28: =INDEX('Feiertagsregeln'!$D$7:$D$96,MATCH($K28,'Feiertagsregeln'!$A$7:$A$96,0)) -> Pfingstmontag | F28: =INDEX('Feiertagsregeln'!$E$7:$E$96,MATCH($K28,'Feiertagsregeln'!$A$7:$A$96,0)) -> Lundi de Pentecôte | G28: =IF(INDEX('Feiertagsregeln'!$F$7:$F$96,MATCH($K28,'Feiertagsregeln'!$A$7:$A$96,0))="","Noch zu erfassen",INDEX('Feiertagsregeln'!$F$7:$F$96,MATCH($K28,'Feiertagsregeln'!$A$7:$A$96,0))) -> Noch zu erfassen | H28: =IF(INDEX('Feiertagsregeln'!$G$7:$G$96,MATCH($K28,'Feiertagsregeln'!$A$7:$A$96,0))="","Noch zu erfassen",INDEX('Feiertagsregeln'!$G$7:$G$96,MATCH($K28,'Feiertagsregeln'!$A$7:$A$96,0))) -> Noch zu erfassen | I28: =INDEX('Feiertagsregeln'!$H$7:$H$96,MATCH($K28,'Feiertagsregeln'!$A$7:$A$96,0)) -> labourLawHoliday | J28: open | K28: AG-WORK-HOL-A-WHIT-MONDAY | L28: =INDEX('Feiertagsregeln'!$Y$7:$Y$96,MATCH($K28,'Feiertagsregeln'!$A$7:$A$96,0)) -> SRC-AG-EGARR-20250901 | M28: =INDEX('Feiertagsregeln'!$Z$7:$Z$96,MATCH($K28,'Feiertagsregeln'!$A$7:$A$96,0)) -> § 6 Abs. 1 Bst. a | N28: Normliste erfasst, Fachfreigabe offen
A29: =INDEX('Feiertagsregeln'!$X$7:$X$96,MATCH($K29,'Feiertagsregeln'!$A$7:$A$96,0)) -> 46746 | B29: =IF(ISNUMBER(A29),CHOOSE(WEEKDAY(A29,2),"Montag","Dienstag","Mittwoch","Donnerstag","Freitag","Samstag","Sonntag"),"n.a.") -> Samstag | C29: CH-AG | D29: Bezirke Aarau, Brugg, Kulm, Lenzburg und Zofingen | E29: =INDEX('Feiertagsregeln'!$D$7:$D$96,MATCH($K29,'Feiertagsregeln'!$A$7:$A$96,0)) -> Weihnachten | F29: =INDEX('Feiertagsregeln'!$E$7:$E$96,MATCH($K29,'Feiertagsregeln'!$A$7:$A$96,0)) -> Noël | G29: =IF(INDEX('Feiertagsregeln'!$F$7:$F$96,MATCH($K29,'Feiertagsregeln'!$A$7:$A$96,0))="","Noch zu erfassen",INDEX('Feiertagsregeln'!$F$7:$F$96,MATCH($K29,'Feiertagsregeln'!$A$7:$A$96,0))) -> Noch zu erfassen | H29: =IF(INDEX('Feiertagsregeln'!$G$7:$G$96,MATCH($K29,'Feiertagsregeln'!$A$7:$A$96,0))="","Noch zu erfassen",INDEX('Feiertagsregeln'!$G$7:$G$96,MATCH($K29,'Feiertagsregeln'!$A$7:$A$96,0))) -> Noch zu erfassen | I29: =INDEX('Feiertagsregeln'!$H$7:$H$96,MATCH($K29,'Feiertagsregeln'!$A$7:$A$96,0)) -> labourLawHoliday | J29: open | K29: AG-WORK-HOL-A-CHRISTMAS | L29: =INDEX('Feiertagsregeln'!$Y$7:$Y$96,MATCH($K29,'Feiertagsregeln'!$A$7:$A$96,0)) -> SRC-AG-EGARR-20250901 | M29: =INDEX('Feiertagsregeln'!$Z$7:$Z$96,MATCH($K29,'Feiertagsregeln'!$A$7:$A$96,0)) -> § 6 Abs. 1 Bst. a | N29: Normliste erfasst, Fachfreigabe offen
A30: =INDEX('Feiertagsregeln'!$X$7:$X$96,MATCH($K30,'Feiertagsregeln'!$A$7:$A$96,0)) -> 46747 | B30: =IF(ISNUMBER(A30),CHOOSE(WEEKDAY(A30,2),"Montag","Dienstag","Mittwoch","Donnerstag","Freitag","Samstag","Sonntag"),"n.a.") -> Sonntag | C30: CH-AG | D30: Bezirke Aarau, Brugg, Kulm, Lenzburg und Zofingen | E30: =INDEX('Feiertagsregeln'!$D$7:$D$96,MATCH($K30,'Feiertagsregeln'!$A$7:$A$96,0)) -> Stephanstag | F30: =INDEX('Feiertagsregeln'!$E$7:$E$96,MATCH($K30,'Feiertagsregeln'!$A$7:$A$96,0)) -> Saint-Étienne | G30: =IF(INDEX('Feiertagsregeln'!$F$7:$F$96,MATCH($K30,'Feiertagsregeln'!$A$7:$A$96,0))="","Noch zu erfassen",INDEX('Feiertagsregeln'!$F$7:$F$96,MATCH($K30,'Feiertagsregeln'!$A$7:$A$96,0))) -> Noch zu erfassen | H30: =IF(INDEX('Feiertagsregeln'!$G$7:$G$96,MATCH($K30,'Feiertagsregeln'!$A$7:$A$96,0))="","Noch zu erfassen",INDEX('Feiertagsregeln'!$G$7:$G$96,MATCH($K30,'Feiertagsregeln'!$A$7:$A$96,0))) -> Noch zu erfassen | I30: =INDEX('Feiertagsregeln'!$H$7:$H$96,MATCH($K30,'Feiertagsregeln'!$A$7:$A$96,0)) -> labourLawHoliday | J30: open | K30: AG-WORK-HOL-A-ST-STEPHEN | L30: =INDEX('Feiertagsregeln'!$Y$7:$Y$96,MATCH($K30,'Feiertagsregeln'!$A$7:$A$96,0)) -> SRC-AG-EGARR-20250901 | M30: =INDEX('Feiertagsregeln'!$Z$7:$Z$96,MATCH($K30,'Feiertagsregeln'!$A$7:$A$96,0)) -> § 6 Abs. 1 Bst. a | N30: Normliste erfasst, Fachfreigabe offen
A31: =INDEX('Feiertagsregeln'!$X$7:$X$96,MATCH($K31,'Feiertagsregeln'!$A$7:$A$96,0)) -> 46388 | B31: =IF(ISNUMBER(A31),CHOOSE(WEEKDAY(A31,2),"Montag","Dienstag","Mittwoch","Donnerstag","Freitag","Samstag","Sonntag"),"n.a.") -> Freitag | C31: CH-AG | D31: Gemeinde Bergdietikon | E31: =INDEX('Feiertagsregeln'!$D$7:$D$96,MATCH($K31,'Feiertagsregeln'!$A$7:$A$96,0)) -> Neujahr | F31: =INDEX('Feiertagsregeln'!$E$7:$E$96,MATCH($K31,'Feiertagsregeln'!$A$7:$A$96,0)) -> Nouvel An | G31: =IF(INDEX('Feiertagsregeln'!$F$7:$F$96,MATCH($K31,'Feiertagsregeln'!$A$7:$A$96,0))="","Noch zu erfassen",INDEX('Feiertagsregeln'!$F$7:$F$96,MATCH($K31,'Feiertagsregeln'!$A$7:$A$96,0))) -> Noch zu erfassen | H31: =IF(INDEX('Feiertagsregeln'!$G$7:$G$96,MATCH($K31,'Feiertagsregeln'!$A$7:$A$96,0))="","Noch zu erfassen",INDEX('Feiertagsregeln'!$G$7:$G$96,MATCH($K31,'Feiertagsregeln'!$A$7:$A$96,0))) -> Noch zu erfassen | I31: =INDEX('Feiertagsregeln'!$H$7:$H$96,MATCH($K31,'Feiertagsregeln'!$A$7:$A$96,0)) -> labourLawHoliday | J31: open | K31: AG-WORK-HOL-B1-NEW-YEAR | L31: =INDEX('Feiertagsregeln'!$Y$7:$Y$96,MATCH($K31,'Feiertagsregeln'!$A$7:$A$96,0)) -> SRC-AG-EGARR-20250901 | M31: =INDEX('Feiertagsregeln'!$Z$7:$Z$96,MATCH($K31,'Feiertagsregeln'!$A$7:$A$96,0)) -> § 6 Abs. 1 Bst. b Ziff. 1 | N31: Normliste erfasst, Fachfreigabe offen
... A105: =INDEX('Feiertagsregeln'!$X$7:$X$96,MATCH($K105,'Feiertagsregeln'!$A$7:$A$96,0)) -> 46600 | B105: =IF(ISNUMBER(A105),CHOOSE(WEEKDAY(A105,2),"Montag","Dienstag","Mittwoch","Donnerstag","Freitag","Samstag","Sonntag"),"n.a.") -> Sonntag | C105: CH-AG | D105: Bezirk Zurzach | E105: =INDEX('Feiertagsregeln'!$D$7:$D$96,MATCH($K105,'Feiertagsregeln'!$A$7:$A$96,0)) -> Bundesfeiertag | F105: =INDEX('Feiertagsregeln'!$E$7:$E$96,MATCH($K105,'Feiertagsregeln'!$A$7:$A$96,0)) -> Fête nationale | G105: =IF(INDEX('Feiertagsregeln'!$F$7:$F$96,MATCH($K105,'Feiertagsregeln'!$A$7:$A$96,0))="","Noch zu erfassen",INDEX('Feiertagsregeln'!$F$7:$F$96,MATCH($K105,'Feiertagsregeln'!$A$7:$A$96,0))) -> Noch zu erfassen | H105: =IF(INDEX('Feiertagsregeln'!$G$7:$G$96,MATCH($K105,'Feiertagsregeln'!$A$7:$A$96,0))="","Noch zu erfassen",INDEX('Feiertagsregeln'!$G$7:$G$96,MATCH($K105,'Feiertagsregeln'!$A$7:$A$96,0))) -> Noch zu erfassen | I105: =INDEX('Feiertagsregeln'!$H$7:$H$96,MATCH($K105,'Feiertagsregeln'!$A$7:$A$96,0)) -> publicHoliday | J105: open | K105: CH-CAL-HOL-NATIONAL-DAY | L105: =INDEX('Feiertagsregeln'!$Y$7:$Y$96,MATCH($K105,'Feiertagsregeln'!$A$7:$A$96,0)) -> SRC-BUNDESFEIERTAG-19940701 | M105: =INDEX('Feiertagsregeln'!$Z$7:$Z$96,MATCH($K105,'Feiertagsregeln'!$A$7:$A$96,0)) -> Art. 1 | N105: Normliste erfasst, Fachfreigabe offen
A106: =INDEX('Feiertagsregeln'!$X$7:$X$122,MATCH($K106,'Feiertagsregeln'!$A$7:$A$122,0)) -> 46388 | B106: =IF(ISNUMBER(A106),CHOOSE(WEEKDAY(A106,2),"Montag","Dienstag","Mittwoch","Donnerstag","Freitag","Samstag","Sonntag"),"n.a.") -> Freitag | C106: CH-TI | D106: Tessin, offizielle Feiertage | E106: =INDEX('Feiertagsregeln'!$D$7:$D$122,MATCH($K106,'Feiertagsregeln'!$A$7:$A$122,0)) -> Neujahr | F106: =INDEX('Feiertagsregeln'!$E$7:$E$122,MATCH($K106,'Feiertagsregeln'!$A$7:$A$122,0)) -> Nouvel An | G106: =IF(INDEX('Feiertagsregeln'!$F$7:$F$122,MATCH($K106,'Feiertagsregeln'!$A$7:$A$122,0))="","Noch zu erfassen",INDEX('Feiertagsregeln'!$F$7:$F$122,MATCH($K106,'Feiertagsregeln'!$A$7:$A$122,0))) -> Capo d’anno | H106: =IF(INDEX('Feiertagsregeln'!$G$7:$G$122,MATCH($K106,'Feiertagsregeln'!$A$7:$A$122,0))="","Noch zu erfassen",INDEX('Feiertagsregeln'!$G$7:$G$122,MATCH($K106,'Feiertagsregeln'!$A$7:$A$122,0))) -> Bumaun | I106: =INDEX('Feiertagsregeln'!$H$7:$H$122,MATCH($K106,'Feiertagsregeln'!$A$7:$A$122,0)) -> publicHoliday | J106: open | K106: TI-CAL-DAY-NEW-YEAR | L106: =INDEX('Feiertagsregeln'!$Y$7:$Y$122,MATCH($K106,'Feiertagsregeln'!$A$7:$A$122,0)) -> SRC-TI-FEIERTAGE-843200 | M106: =INDEX('Feiertagsregeln'!$Z$7:$Z$122,MATCH($K106,'Feiertagsregeln'!$A$7:$A$122,0)) -> Art. 1 | N106: Offizielle Feiertage. LPAmm-Zuordnung zur Fachprüfung
A107: =INDEX('Feiertagsregeln'!$X$7:$X$122,MATCH($K107,'Feiertagsregeln'!$A$7:$A$122,0)) -> 46393 | B107: =IF(ISNUMBER(A107),CHOOSE(WEEKDAY(A107,2),"Montag","Dienstag","Mittwoch","Donnerstag","Freitag","Samstag","Sonntag"),"n.a.") -> Mittwoch | C107: CH-TI | D107: Tessin, offizielle Feiertage | E107: =INDEX('Feiertagsregeln'!$D$7:$D$122,MATCH($K107,'Feiertagsregeln'!$A$7:$A$122,0)) -> Heilige Drei Könige | F107: =INDEX('Feiertagsregeln'!$E$7:$E$122,MATCH($K107,'Feiertagsregeln'!$A$7:$A$122,0)) -> Épiphanie | G107: =IF(INDEX('Feiertagsregeln'!$F$7:$F$122,MATCH($K107,'Feiertagsregeln'!$A$7:$A$122,0))="","Noch zu erfassen",INDEX('Feiertagsregeln'!$F$7:$F$122,MATCH($K107,'Feiertagsregeln'!$A$7:$A$122,0))) -> Epifania | H107: =IF(INDEX('Feiertagsregeln'!$G$7:$G$122,MATCH($K107,'Feiertagsregeln'!$A$7:$A$122,0))="","Noch zu erfassen",INDEX('Feiertagsregeln'!$G$7:$G$122,MATCH($K107,'Feiertagsregeln'!$A$7:$A$122,0))) -> Bavania | I107: =INDEX('Feiertagsregeln'!$H$7:$H$122,MATCH($K107,'Feiertagsregeln'!$A$7:$A$122,0)) -> publicHoliday | J107: open | K107: TI-CAL-DAY-EPIPHANY | L107: =INDEX('Feiertagsregeln'!$Y$7:$Y$122,MATCH($K107,'Feiertagsregeln'!$A$7:$A$122,0)) -> SRC-TI-FEIERTAGE-843200 | M107: =INDEX('Feiertagsregeln'!$Z$7:$Z$122,MATCH($K107,'Feiertagsregeln'!$A$7:$A$122,0)) -> Art. 1 | N107: LPAmm-Zuordnung zur Fachprüfung. RG: provisorische Produktübersetzung.
A108: =INDEX('Feiertagsregeln'!$X$7:$X$122,MATCH($K108,'Feiertagsregeln'!$A$7:$A$122,0)) -> 46465 | B108: =IF(ISNUMBER(A108),CHOOSE(WEEKDAY(A108,2),"Montag","Dienstag","Mittwoch","Donnerstag","Freitag","Samstag","Sonntag"),"n.a.") -> Freitag | C108: CH-TI | D108: Tessin, offizielle Feiertage | E108: =INDEX('Feiertagsregeln'!$D$7:$D$122,MATCH($K108,'Feiertagsregeln'!$A$7:$A$122,0)) -> Josefstag | F108: =INDEX('Feiertagsregeln'!$E$7:$E$122,MATCH($K108,'Feiertagsregeln'!$A$7:$A$122,0)) -> Saint-Joseph | G108: =IF(INDEX('Feiertagsregeln'!$F$7:$F$122,MATCH($K108,'Feiertagsregeln'!$A$7:$A$122,0))="","Noch zu erfassen",INDEX('Feiertagsregeln'!$F$7:$F$122,MATCH($K108,'Feiertagsregeln'!$A$7:$A$122,0))) -> San Giuseppe | H108: =IF(INDEX('Feiertagsregeln'!$G$7:$G$122,MATCH($K108,'Feiertagsregeln'!$A$7:$A$122,0))="","Noch zu erfassen",INDEX('Feiertagsregeln'!$G$7:$G$122,MATCH($K108,'Feiertagsregeln'!$A$7:$A$122,0))) -> Son Giusep | I108: =INDEX('Feiertagsregeln'!$H$7:$H$122,MATCH($K108,'Feiertagsregeln'!$A$7:$A$122,0)) -> publicHoliday | J108: open | K108: TI-CAL-DAY-ST-JOSEPH | L108: =INDEX('Feiertagsregeln'!$Y$7:$Y$122,MATCH($K108,'Feiertagsregeln'!$A$7:$A$122,0)) -> SRC-TI-FEIERTAGE-843200 | M108: =INDEX('Feiertagsregeln'!$Z$7:$Z$122,MATCH($K108,'Feiertagsregeln'!$A$7:$A$122,0)) -> Art. 1 | N108: LPAmm-Zuordnung zur Fachprüfung. RG: provisorische Produktübersetzung.
A109: =INDEX('Feiertagsregeln'!$X$7:$X$122,MATCH($K109,'Feiertagsregeln'!$A$7:$A$122,0)) -> 46475 | B109: =IF(ISNUMBER(A109),CHOOSE(WEEKDAY(A109,2),"Montag","Dienstag","Mittwoch","Donnerstag","Freitag","Samstag","Sonntag"),"n.a.") -> Montag | C109: CH-TI | D109: Tessin, offizielle Feiertage | E109: =INDEX('Feiertagsregeln'!$D$7:$D$122,MATCH($K109,'Feiertagsregeln'!$A$7:$A$122,0)) -> Ostermontag | F109: =INDEX('Feiertagsregeln'!$E$7:$E$122,MATCH($K109,'Feiertagsregeln'!$A$7:$A$122,0)) -> Lundi de Pâques | G109: =IF(INDEX('Feiertagsregeln'!$F$7:$F$122,MATCH($K109,'Feiertagsregeln'!$A$7:$A$122,0))="","Noch zu erfassen",INDEX('Feiertagsregeln'!$F$7:$F$122,MATCH($K109,'Feiertagsregeln'!$A$7:$A$122,0))) -> Lunedì di Pasqua | H109: =IF(INDEX('Feiertagsregeln'!$G$7:$G$122,MATCH($K109,'Feiertagsregeln'!$A$7:$A$122,0))="","Noch zu erfassen",INDEX('Feiertagsregeln'!$G$7:$G$122,MATCH($K109,'Feiertagsregeln'!$A$7:$A$122,0))) -> Glindesdi da Pasca | I109: =INDEX('Feiertagsregeln'!$H$7:$H$122,MATCH($K109,'Feiertagsregeln'!$A$7:$A$122,0)) -> publicHoliday | J109: open | K109: TI-CAL-DAY-EASTER-MONDAY | L109: =INDEX('Feiertagsregeln'!$Y$7:$Y$122,MATCH($K109,'Feiertagsregeln'!$A$7:$A$122,0)) -> SRC-TI-FEIERTAGE-843200 | M109: =INDEX('Feiertagsregeln'!$Z$7:$Z$122,MATCH($K109,'Feiertagsregeln'!$A$7:$A$122,0)) -> Art. 1 | N109: Offizielle Feiertage. LPAmm-Zuordnung zur Fachprüfung
A110: =INDEX('Feiertagsregeln'!$X$7:$X$122,MATCH($K110,'Feiertagsregeln'!$A$7:$A$122,0)) -> 46508 | B110: =IF(ISNUMBER(A110),CHOOSE(WEEKDAY(A110,2),"Montag","Dienstag","Mittwoch","Donnerstag","Freitag","Samstag","Sonntag"),"n.a.") -> Samstag | C110: CH-TI | D110: Tessin, offizielle Feiertage | E110: =INDEX('Feiertagsregeln'!$D$7:$D$122,MATCH($K110,'Feiertagsregeln'!$A$7:$A$122,0)) -> Tag der Arbeit (1. Mai) | F110: =INDEX('Feiertagsregeln'!$E$7:$E$122,MATCH($K110,'Feiertagsregeln'!$A$7:$A$122,0)) -> Fête du travail (1er mai) | G110: =IF(INDEX('Feiertagsregeln'!$F$7:$F$122,MATCH($K110,'Feiertagsregeln'!$A$7:$A$122,0))="","Noch zu erfassen",INDEX('Feiertagsregeln'!$F$7:$F$122,MATCH($K110,'Feiertagsregeln'!$A$7:$A$122,0))) -> Primo maggio | H110: =IF(INDEX('Feiertagsregeln'!$G$7:$G$122,MATCH($K110,'Feiertagsregeln'!$A$7:$A$122,0))="","Noch zu erfassen",INDEX('Feiertagsregeln'!$G$7:$G$122,MATCH($K110,'Feiertagsregeln'!$A$7:$A$122,0))) -> Di da la lavur (1. da matg) | I110: =INDEX('Feiertagsregeln'!$H$7:$H$122,MATCH($K110,'Feiertagsregeln'!$A$7:$A$122,0)) -> publicHoliday | J110: open | K110: TI-CAL-DAY-MAY1 | L110: =INDEX('Feiertagsregeln'!$Y$7:$Y$122,MATCH($K110,'Feiertagsregeln'!$A$7:$A$122,0)) -> SRC-TI-FEIERTAGE-843200 | M110: =INDEX('Feiertagsregeln'!$Z$7:$Z$122,MATCH($K110,'Feiertagsregeln'!$A$7:$A$122,0)) -> Art. 1 | N110: LPAmm-Zuordnung zur Fachprüfung. RG: provisorische Produktübersetzung.
A111: =INDEX('Feiertagsregeln'!$X$7:$X$122,MATCH($K111,'Feiertagsregeln'!$A$7:$A$122,0)) -> 46513 | B111: =IF(ISNUMBER(A111),CHOOSE(WEEKDAY(A111,2),"Montag","Dienstag","Mittwoch","Donnerstag","Freitag","Samstag","Sonntag"),"n.a.") -> Donnerstag | C111: CH-TI | D111: Tessin, offizielle Feiertage | E111: =INDEX('Feiertagsregeln'!$D$7:$D$122,MATCH($K111,'Feiertagsregeln'!$A$7:$A$122,0)) -> Auffahrt | F111: =INDEX('Feiertagsregeln'!$E$7:$E$122,MATCH($K111,'Feiertagsregeln'!$A$7:$A$122,0)) -> Ascension | G111: =IF(INDEX('Feiertagsregeln'!$F$7:$F$122,MATCH($K111,'Feiertagsregeln'!$A$7:$A$122,0))="","Noch zu erfassen",INDEX('Feiertagsregeln'!$F$7:$F$122,MATCH($K111,'Feiertagsregeln'!$A$7:$A$122,0))) -> Ascensione | H111: =IF(INDEX('Feiertagsregeln'!$G$7:$G$122,MATCH($K111,'Feiertagsregeln'!$A$7:$A$122,0))="","Noch zu erfassen",INDEX('Feiertagsregeln'!$G$7:$G$122,MATCH($K111,'Feiertagsregeln'!$A$7:$A$122,0))) -> Ascensiun | I111: =INDEX('Feiertagsregeln'!$H$7:$H$122,MATCH($K111,'Feiertagsregeln'!$A$7:$A$122,0)) -> publicHoliday | J111: open | K111: TI-CAL-DAY-ASCENSION | L111: =INDEX('Feiertagsregeln'!$Y$7:$Y$122,MATCH($K111,'Feiertagsregeln'!$A$7:$A$122,0)) -> SRC-TI-FEIERTAGE-843200 | M111: =INDEX('Feiertagsregeln'!$Z$7:$Z$122,MATCH($K111,'Feiertagsregeln'!$A$7:$A$122,0)) -> Art. 1 | N111: Offizielle Feiertage. LPAmm-Zuordnung zur Fachprüfung
A112: =INDEX('Feiertagsregeln'!$X$7:$X$122,MATCH($K112,'Feiertagsregeln'!$A$7:$A$122,0)) -> 46524 | B112: =IF(ISNUMBER(A112),CHOOSE(WEEKDAY(A112,2),"Montag","Dienstag","Mittwoch","Donnerstag","Freitag","Samstag","Sonntag"),"n.a.") -> Montag | C112: CH-TI | D112: Tessin, offizielle Feiertage | E112: =INDEX('Feiertagsregeln'!$D$7:$D$122,MATCH($K112,'Feiertagsregeln'!$A$7:$A$122,0)) -> Pfingstmontag | F112: =INDEX('Feiertagsregeln'!$E$7:$E$122,MATCH($K112,'Feiertagsregeln'!$A$7:$A$122,0)) -> Lundi de Pentecôte | G112: =IF(INDEX('Feiertagsregeln'!$F$7:$F$122,MATCH($K112,'Feiertagsregeln'!$A$7:$A$122,0))="","Noch zu erfassen",INDEX('Feiertagsregeln'!$F$7:$F$122,MATCH($K112,'Feiertagsregeln'!$A$7:$A$122,0))) -> Lunedì di Pentecoste | H112: =IF(INDEX('Feiertagsregeln'!$G$7:$G$122,MATCH($K112,'Feiertagsregeln'!$A$7:$A$122,0))="","Noch zu erfassen",INDEX('Feiertagsregeln'!$G$7:$G$122,MATCH($K112,'Feiertagsregeln'!$A$7:$A$122,0))) -> Glindesdi da Tschuncaisma | I112: =INDEX('Feiertagsregeln'!$H$7:$H$122,MATCH($K112,'Feiertagsregeln'!$A$7:$A$122,0)) -> publicHoliday | J112: open | K112: TI-CAL-DAY-WHIT-MONDAY | L112: =INDEX('Feiertagsregeln'!$Y$7:$Y$122,MATCH($K112,'Feiertagsregeln'!$A$7:$A$122,0)) -> SRC-TI-FEIERTAGE-843200 | M112: =INDEX('Feiertagsregeln'!$Z$7:$Z$122,MATCH($K112,'Feiertagsregeln'!$A$7:$A$122,0)) -> Art. 1 | N112: Offizielle Feiertage. LPAmm-Zuordnung zur Fachprüfung
A113: =INDEX('Feiertagsregeln'!$X$7:$X$122,MATCH($K113,'Feiertagsregeln'!$A$7:$A$122,0)) -> 46534 | B113: =IF(ISNUMBER(A113),CHOOSE(WEEKDAY(A113,2),"Montag","Dienstag","Mittwoch","Donnerstag","Freitag","Samstag","Sonntag"),"n.a.") -> Donnerstag | C113: CH-TI | D113: Tessin, offizielle Feiertage | E113: =INDEX('Feiertagsregeln'!$D$7:$D$122,MATCH($K113,'Feiertagsregeln'!$A$7:$A$122,0)) -> Fronleichnam | F113: =INDEX('Feiertagsregeln'!$E$7:$E$122,MATCH($K113,'Feiertagsregeln'!$A$7:$A$122,0)) -> Fête-Dieu | G113: =IF(INDEX('Feiertagsregeln'!$F$7:$F$122,MATCH($K113,'Feiertagsregeln'!$A$7:$A$122,0))="","Noch zu erfassen",INDEX('Feiertagsregeln'!$F$7:$F$122,MATCH($K113,'Feiertagsregeln'!$A$7:$A$122,0))) -> Corpus Domini | H113: =IF(INDEX('Feiertagsregeln'!$G$7:$G$122,MATCH($K113,'Feiertagsregeln'!$A$7:$A$122,0))="","Noch zu erfassen",INDEX('Feiertagsregeln'!$G$7:$G$122,MATCH($K113,'Feiertagsregeln'!$A$7:$A$122,0))) -> Sontgilcrest | I113: =INDEX('Feiertagsregeln'!$H$7:$H$122,MATCH($K113,'Feiertagsregeln'!$A$7:$A$122,0)) -> publicHoliday | J113: open | K113: TI-CAL-DAY-CORPUS-CHRISTI | L113: =INDEX('Feiertagsregeln'!$Y$7:$Y$122,MATCH($K113,'Feiertagsregeln'!$A$7:$A$122,0)) -> SRC-TI-FEIERTAGE-843200 | M113: =INDEX('Feiertagsregeln'!$Z$7:$Z$122,MATCH($K113,'Feiertagsregeln'!$A$7:$A$122,0)) -> Art. 1 | N113: LPAmm-Zuordnung zur Fachprüfung. RG: provisorische Produktübersetzung.
A114: =INDEX('Feiertagsregeln'!$X$7:$X$122,MATCH($K114,'Feiertagsregeln'!$A$7:$A$122,0)) -> 46567 | B114: =IF(ISNUMBER(A114),CHOOSE(WEEKDAY(A114,2),"Montag","Dienstag","Mittwoch","Donnerstag","Freitag","Samstag","Sonntag"),"n.a.") -> Dienstag | C114: CH-TI | D114: Tessin, offizielle Feiertage | E114: =INDEX('Feiertagsregeln'!$D$7:$D$122,MATCH($K114,'Feiertagsregeln'!$A$7:$A$122,0)) -> Peter und Paul | F114: =INDEX('Feiertagsregeln'!$E$7:$E$122,MATCH($K114,'Feiertagsregeln'!$A$7:$A$122,0)) -> Saints Pierre et Paul | G114: =IF(INDEX('Feiertagsregeln'!$F$7:$F$122,MATCH($K114,'Feiertagsregeln'!$A$7:$A$122,0))="","Noch zu erfassen",INDEX('Feiertagsregeln'!$F$7:$F$122,MATCH($K114,'Feiertagsregeln'!$A$7:$A$122,0))) -> San Pietro e Paolo | H114: =IF(INDEX('Feiertagsregeln'!$G$7:$G$122,MATCH($K114,'Feiertagsregeln'!$A$7:$A$122,0))="","Noch zu erfassen",INDEX('Feiertagsregeln'!$G$7:$G$122,MATCH($K114,'Feiertagsregeln'!$A$7:$A$122,0))) -> Son Peder e son Paul | I114: =INDEX('Feiertagsregeln'!$H$7:$H$122,MATCH($K114,'Feiertagsregeln'!$A$7:$A$122,0)) -> publicHoliday | J114: open | K114: TI-CAL-DAY-ST-PETER-PAUL | L114: =INDEX('Feiertagsregeln'!$Y$7:$Y$122,MATCH($K114,'Feiertagsregeln'!$A$7:$A$122,0)) -> SRC-TI-FEIERTAGE-843200 | M114: =INDEX('Feiertagsregeln'!$Z$7:$Z$122,MATCH($K114,'Feiertagsregeln'!$A$7:$A$122,0)) -> Art. 1 | N114: LPAmm-Zuordnung zur Fachprüfung. RG: provisorische Produktübersetzung.
A115: =INDEX('Feiertagsregeln'!$X$7:$X$122,MATCH($K115,'Feiertagsregeln'!$A$7:$A$122,0)) -> 46600 | B115: =IF(ISNUMBER(A115),CHOOSE(WEEKDAY(A115,2),"Montag","Dienstag","Mittwoch","Donnerstag","Freitag","Samstag","Sonntag"),"n.a.") -> Sonntag | C115: CH-TI | D115: Tessin, offizielle Feiertage | E115: =INDEX('Feiertagsregeln'!$D$7:$D$122,MATCH($K115,'Feiertagsregeln'!$A$7:$A$122,0)) -> Bundesfeiertag | F115: =INDEX('Feiertagsregeln'!$E$7:$E$122,MATCH($K115,'Feiertagsregeln'!$A$7:$A$122,0)) -> Fête nationale | G115: =IF(INDEX('Feiertagsregeln'!$F$7:$F$122,MATCH($K115,'Feiertagsregeln'!$A$7:$A$122,0))="","Noch zu erfassen",INDEX('Feiertagsregeln'!$F$7:$F$122,MATCH($K115,'Feiertagsregeln'!$A$7:$A$122,0))) -> Primo agosto | H115: =IF(INDEX('Feiertagsregeln'!$G$7:$G$122,MATCH($K115,'Feiertagsregeln'!$A$7:$A$122,0))="","Noch zu erfassen",INDEX('Feiertagsregeln'!$G$7:$G$122,MATCH($K115,'Feiertagsregeln'!$A$7:$A$122,0))) -> Festa naziunala svizra | I115: =INDEX('Feiertagsregeln'!$H$7:$H$122,MATCH($K115,'Feiertagsregeln'!$A$7:$A$122,0)) -> publicHoliday | J115: open | K115: TI-CAL-DAY-NATIONAL-DAY | L115: =INDEX('Feiertagsregeln'!$Y$7:$Y$122,MATCH($K115,'Feiertagsregeln'!$A$7:$A$122,0)) -> SRC-TI-FEIERTAGE-843200 | M115: =INDEX('Feiertagsregeln'!$Z$7:$Z$122,MATCH($K115,'Feiertagsregeln'!$A$7:$A$122,0)) -> Art. 1 | N115: Offizielle Feiertage. LPAmm-Zuordnung zur Fachprüfung
A116: =INDEX('Feiertagsregeln'!$X$7:$X$122,MATCH($K116,'Feiertagsregeln'!$A$7:$A$122,0)) -> 46614 | B116: =IF(ISNUMBER(A116),CHOOSE(WEEKDAY(A116,2),"Montag","Dienstag","Mittwoch","Donnerstag","Freitag","Samstag","Sonntag"),"n.a.") -> Sonntag | C116: CH-TI | D116: Tessin, offizielle Feiertage | E116: =INDEX('Feiertagsregeln'!$D$7:$D$122,MATCH($K116,'Feiertagsregeln'!$A$7:$A$122,0)) -> Mariä Himmelfahrt | F116: =INDEX('Feiertagsregeln'!$E$7:$E$122,MATCH($K116,'Feiertagsregeln'!$A$7:$A$122,0)) -> Assomption | G116: =IF(INDEX('Feiertagsregeln'!$F$7:$F$122,MATCH($K116,'Feiertagsregeln'!$A$7:$A$122,0))="","Noch zu erfassen",INDEX('Feiertagsregeln'!$F$7:$F$122,MATCH($K116,'Feiertagsregeln'!$A$7:$A$122,0))) -> Assunzione | H116: =IF(INDEX('Feiertagsregeln'!$G$7:$G$122,MATCH($K116,'Feiertagsregeln'!$A$7:$A$122,0))="","Noch zu erfassen",INDEX('Feiertagsregeln'!$G$7:$G$122,MATCH($K116,'Feiertagsregeln'!$A$7:$A$122,0))) -> Nossadunna d’avust | I116: =INDEX('Feiertagsregeln'!$H$7:$H$122,MATCH($K116,'Feiertagsregeln'!$A$7:$A$122,0)) -> publicHoliday | J116: open | K116: TI-CAL-DAY-ASSUMPTION | L116: =INDEX('Feiertagsregeln'!$Y$7:$Y$122,MATCH($K116,'Feiertagsregeln'!$A$7:$A$122,0)) -> SRC-TI-FEIERTAGE-843200 | M116: =INDEX('Feiertagsregeln'!$Z$7:$Z$122,MATCH($K116,'Feiertagsregeln'!$A$7:$A$122,0)) -> Art. 1 | N116: LPAmm-Zuordnung zur Fachprüfung. RG: provisorische Produktübersetzung.
...

Sheet Gemeinwesen
A2: Gemeinwesen und Bearbeitungsstand
A4: Erfassungsstand und fachliche Freigabe sind getrennt. Leere Quellen sind noch zu erheben.
A6: Code | B6: Deutsch | C6: Französisch | D6: Italienisch | E6: Rumantsch Grischun | F6: Übergeordnet | G6: Erfassungsstand | H6: Fachstatus | I6: Amtliche Feiertagsquelle
A7: CH | B7: Bund | C7: Confédération | G7: Referenzpilot | H7: approved | I7: https://www.fedlex.admin.ch/eli/cc/1994/1340_1340_1340/de
A8: CH-ZH | B8: Zürich | C8: Zurich | F8: CH | G8: Nicht erhoben | H8: open | I8: Noch zu erheben
A9: CH-BE | B9: Bern | C9: Berne | F9: CH | G9: Referenzpilot | H9: approved | I9: https://www.belex.sites.be.ch/app/de/texts_of_law/555.1
A10: CH-LU | B10: Luzern | C10: Lucerne | F10: CH | G10: Nicht erhoben | H10: open | I10: Noch zu erheben
A11: CH-UR | B11: Uri | C11: Uri | F11: CH | G11: Nicht erhoben | H11: open | I11: Noch zu erheben
A12: CH-SZ | B12: Schwyz | C12: Schwytz | F12: CH | G12: Nicht erhoben | H12: open | I12: Noch zu erheben
A13: CH-OW | B13: Obwalden | C13: Obwald | F13: CH | G13: Nicht erhoben | H13: open | I13: Noch zu erheben
A14: CH-NW | B14: Nidwalden | C14: Nidwald | F14: CH | G14: Nicht erhoben | H14: open | I14: Noch zu erheben
A15: CH-GL | B15: Glarus | C15: Glaris | F15: CH | G15: Nicht erhoben | H15: open | I15: Noch zu erheben
A16: CH-ZG | B16: Zug | C16: Zoug | F16: CH | G16: Nicht erhoben | H16: open | I16: Noch zu erheben
A17: CH-FR | B17: Freiburg | C17: Fribourg | F17: CH | G17: Nicht erhoben | H17: open | I17: Noch zu erheben
A18: CH-SO | B18: Solothurn | C18: Soleure | F18: CH | G18: Nicht erhoben | H18: open | I18: Noch zu erheben
A19: CH-BS | B19: Basel-Stadt | C19: Bâle-Ville | F19: CH | G19: Nicht erhoben | H19: open | I19: Noch zu erheben
... A24: CH-SG | B24: St. Gallen | C24: Saint-Gall | F24: CH | G24: Nicht erhoben | H24: open | I24: Noch zu erheben
A25: CH-GR | B25: Graubünden | C25: Grisons | D25: Grigioni | E25: Grischun | F25: CH | G25: AP18B-02, kantonale Normliste erfasst, Fachabnahme offen | H25: open | I25: https://www.gr-lex.gr.ch/api/de/versions/2604/pdf_file
A26: CH-AG | B26: Aargau | C26: Argovie | F26: CH | G26: Kantonspaket AP18B-01, Fachabnahme offen | H26: open | I26: https://gesetzessammlungen.ag.ch/app/de/texts_of_law/961.200
A27: CH-TG | B27: Thurgau | C27: Thurgovie | F27: CH | G27: Nicht erhoben | H27: open | I27: Noch zu erheben
A28: CH-TI | B28: Tessin | C28: Tessin | D28: Ticino | E28: Tessin | F28: CH | G28: AP18B-02, kantonale Normliste erfasst, Fachabnahme offen | H28: open | I28: https://www3.ti.ch/CAN/RLeggi/public/index.php/raccolta-leggi/legge/num/568
A29: CH-VD | B29: Waadt | C29: Vaud | F29: CH | G29: Nicht erhoben | H29: open | I29: Noch zu erheben
A30: CH-VS | B30: Wallis | C30: Valais | F30: CH | G30: Nicht erhoben | H30: open | I30: Noch zu erheben
A31: CH-NE | B31: Neuenburg | C31: Neuchâtel | F31: CH | G31: Nicht erhoben | H31: open | I31: Noch zu erheben
A32: CH-GE | B32: Genf | C32: Genève | F32: CH | G32: Nicht erhoben | H32: open | I32: Noch zu erheben
A33: CH-JU | B33: Jura | C33: Jura | F33: CH | G33: Nicht erhoben | H33: open | I33: Noch zu erheben

Sheet Feiertagsregeln
A2: Feiertagsregeln und Berechnung
A4: Rechtskategorie und Geltungsbereich sind Pflicht. Datum und Gültigkeit rechts werden aus dem Kalenderjahr berechnet.
A6: Regel-ID | B6: Gemeinwesen | C6: Geltungs-ID | D6: Deutsch | E6: Französisch | F6: Italienisch | G6: Rumantsch Grischun | H6: Rechtskategorie | I6: Regeltyp | J6: Monat | K6: Tag | L6: Osterversatz | M6: ISO-Wochentag | N6: Vorkommen | O6: Gültig ab | P6: Gültig bis | Q6: Priorität | R6: Fachstatus | S6: Freigabebasis | T6: Wirkung | U6: Zielregel | V6: Exportklasse | W6: Rohdatum | X6: Datum im Geltungszeitraum | Y6: Quellen-ID | Z6: Fundstelle | AA6: Osterrechnung | AB6: Wert
A7: CH-CAL-HOL-NATIONAL-DAY | B7: CH | C7: CH-ALL | D7: Bundesfeiertag | E7: Fête nationale | H7: publicHoliday | I7: fixedMonthDay | J7: 8 | K7: 1 | O7: 34516 | Q7: 100 | R7: approved | S7: 2026-08-31-mvp-03-approved.1 | T7: add | V7: referenceOnly | W7: =IF(AND(ISNUMBER('Übersicht'!$B$4),'Übersicht'!$B$4=INT('Übersicht'!$B$4),'Übersicht'!$B$4>=2026,'Übersicht'!$B$4<=2028),IF(I7="fixedMonthDay",IF(AND(ISNUMBER(J7),ISNUMBER(K7),J7=INT(J7),K7=INT(K7),MONTH(DATE('Übersicht'!$B$4,J7,K7))=J7,DAY(DATE('Übersicht'!$B$4,J7,K7))=K7),DATE('Übersicht'!$B$4,J7,K7),NA()),IF(I7="easterOffsetDays",IF(AND(ISNUMBER(L7),L7=INT(L7),ABS(L7)<=366),$AB$23+L7,NA()),IF(I7="nthWeekdayOfMonth",IF(AND(ISNUMBER(J7),ISNUMBER(M7),ISNUMBER(N7),J7=INT(J7),M7=INT(M7),N7=INT(N7),J7>=1,J7<=12,M7>=1,M7<=7,N7>=1,N7<=5,MONTH(DATE('Übersicht'!$B$4,J7,1)+MOD(M7-WEEKDAY(DATE('Übersicht'!$B$4,J7,1),2),7)+7*(N7-1))=J7),DATE('Übersicht'!$B$4,J7,1)+MOD(M7-WEEKDAY(DATE('Übersicht'!$B$4,J7,1),2),7)+7*(N7-1),NA()),NA()))),NA()) -> 46600 | X7: =IF(AND(W7>=O7,OR(P7="",W7<=P7)),W7,"Ausserhalb Geltung") -> 46600 | Y7: SRC-BUNDESFEIERTAG-19940701 | Z7: Art. 1 | AA7: Jahr | AB7: ='Übersicht'!$B$4 -> 2027
A8: BE-CAL-HOL-NEW-YEAR | B8: CH-BE | C8: BE-ALL | D8: Neujahr | E8: Nouvel An | H8: publicHoliday | I8: fixedMonthDay | J8: 1 | K8: 1 | O8: 46023 | Q8: 100 | R8: approved | S8: 2026-08-31-mvp-03-approved.1 | T8: add | V8: referenceOnly | W8: =IF(AND(ISNUMBER('Übersicht'!$B$4),'Übersicht'!$B$4=INT('Übersicht'!$B$4),'Übersicht'!$B$4>=2026,'Übersicht'!$B$4<=2028),IF(I8="fixedMonthDay",IF(AND(ISNUMBER(J8),ISNUMBER(K8),J8=INT(J8),K8=INT(K8),MONTH(DATE('Übersicht'!$B$4,J8,K8))=J8,DAY(DATE('Übersicht'!$B$4,J8,K8))=K8),DATE('Übersicht'!$B$4,J8,K8),NA()),IF(I8="easterOffsetDays",IF(AND(ISNUMBER(L8),L8=INT(L8),ABS(L8)<=366),$AB$23+L8,NA()),IF(I8="nthWeekdayOfMonth",IF(AND(ISNUMBER(J8),ISNUMBER(M8),ISNUMBER(N8),J8=INT(J8),M8=INT(M8),N8=INT(N8),J8>=1,J8<=12,M8>=1,M8<=7,N8>=1,N8<=5,MONTH(DATE('Übersicht'!$B$4,J8,1)+MOD(M8-WEEKDAY(DATE('Übersicht'!$B$4,J8,1),2),7)+7*(N8-1))=J8),DATE('Übersicht'!$B$4,J8,1)+MOD(M8-WEEKDAY(DATE('Übersicht'!$B$4,J8,1),2),7)+7*(N8-1),NA()),NA()))),NA()) -> 46388 | X8: =IF(AND(W8>=O8,OR(P8="",W8<=P8)),W8,"Ausserhalb Geltung") -> 46388 | Y8: SRC-FRG-BE-20210401 | Z8: Art. 2 Abs. 1 Bst. c | AA8: a | AB8: =MOD(AB7,19) -> 13
