Workbook

Sheet Übersicht
A2: STEIMER Feiertagsgrundlage Schweiz
A4: Kalenderjahr | B4: 2028 | D4: Prüfzeitraum 2026–2028
A6: AP18B-04 · V0.10 · Bund und alle 26 Kantone als Arbeitsgrundlage
A8: Alle Kantone erhoben, keine Vollständigkeitsfreigabe. 5 begrenzte Fälle offen, siehe Quellenprüfung.
A9: Abgenommene V0.9 erhalten. SO-Halbtag am 1. Mai: gemäss Fachentscheid keine Fristwirkung.
A10: GR nur kantonale Grundliste. Lokale Ruhetage nicht erhoben, VRG-Annahme dokumentiert.
A11: Gelbes Feld: Jahr ändern. Die Datumswerte werden in Excel neu berechnet.
A12: Im Feiertagskalender nach Gemeinwesen, Geltungsbereich oder Status filtern.
A13: Jede Regeländerung verlangt Fachstatus open und neue Prüfung. Alte Freigabe gilt nicht weiter.
A14: approved bezeichnet nur die angegebene frühere Fachfreigabe, nicht diese Arbeitsmappe.
A15: Quellenprüfung und Datenrelease bleiben getrennt. Neue Prüfereignisse sind candidate.
A16: Keine Makros, externen Datenverbindungen oder automatische Datenaktivierung.
A17: Sonntage gelten separat. Die Ansicht enthält benannte Feiertage, nicht jeden Sonntag.
A18: Gerichtsferien bleiben unverändert in der bestehenden Kalenderkomponente.
... A20: Kalender-App und Feiertagskarte gehören nicht zu AP18.
A23: Kontrolle | B23: Anzahl
A24: Gemeinwesen | B24: =COUNTA(Gemeinwesen!$A$7:$A$33) -> 27 | D24: Stand: 13. September 2026
A25: Referenz-Feiertagsregeln | B25: =COUNTIFS(Feiertagsregeln!$R$7:$R$96,"approved") -> 12 | D25: Fachverantwortung: David Steimer
A26: Offene Kantonsregeln | B26: =COUNTIFS(Feiertagsregeln!$R$7:$R$480,"open") -> 462 | D26: Nächste Jahresprüfung: spätestens 15.11.2027
A29: Pflege: Regeln und Quellen über stabile IDs verknüpfen. Keine Zeilennummer als Identität.
A30: V0.9 ist fachlich abgenommen. Statuswerte früherer Kandidaten bleiben historisch, neue Regeln sind nicht freigegeben.
A31: Der Stand enthält keine neue juristische Freigabe und verändert keine Installation.
A32: Gebiets- und Zuordnungsänderungen brauchen eine Neugenerierung des Kalenders.
A33: Formeln und Referenzzeilen sind geschützt. Blattschutz ohne Passwort aufhebbar.
A34: Vier Sprachspalten erhalten. Neue Produktübersetzungen sind provisorisch, keine amtlichen Sprachfassungen.
A35: Zusätzliche Sprachen nur in der Arbeitsmappe. App und Laufzeitdaten bleiben unverändert.
A36: Arbeitsmappenvertrag 0.5.0 bestätigt (DEC-2026-021). Keine neue Fach-, Produkt- oder Releasefreigabe.

Sheet Feiertagskalender
A2: Generierter Feiertagskalender
A4: Unvollständige Profile AR/AI/GL/NE beachten. SO-Halbtag ohne Fristwirkung. Neue Regeln nicht für Fristen freigegeben.
A6: Datum | B6: Wochentag | C6: Gemeinwesen | D6: Geltungsbereich | E6: Feiertag | F6: Französisch | G6: Italienisch | H6: Rumantsch Grischun | I6: Rechtskategorie | J6: Fachstatus | K6: Regel-ID | L6: Quellen-ID | M6: Fundstelle | N6: Abdeckung | O6: Tagesumfang
A7: =INDEX(Feiertagsregeln!$X$7:$X$480,MATCH($K7,Feiertagsregeln!$A$7:$A$480,0)) -> 46966 | B7: =IF(ISNUMBER(A7),CHOOSE(WEEKDAY(A7,2),"Montag","Dienstag","Mittwoch","Donnerstag","Freitag","Samstag","Sonntag")&IF(O7="Ab 12.00 Uhr",", ab 12.00 Uhr",""),"n.a.") -> Dienstag | C7: CH | D7: Bundesgebiet | E7: =INDEX(Feiertagsregeln!$D$7:$D$480,MATCH($K7,Feiertagsregeln!$A$7:$A$480,0)) -> Bundesfeiertag | F7: =INDEX(Feiertagsregeln!$E$7:$E$480,MATCH($K7,Feiertagsregeln!$A$7:$A$480,0)) -> Fête nationale | G7: =IF(INDEX(Feiertagsregeln!$F$7:$F$480,MATCH($K7,Feiertagsregeln!$A$7:$A$480,0))="","Noch zu erfassen",INDEX(Feiertagsregeln!$F$7:$F$480,MATCH($K7,Feiertagsregeln!$A$7:$A$480,0))) -> Noch zu erfassen | H7: =IF(INDEX(Feiertagsregeln!$G$7:$G$480,MATCH($K7,Feiertagsregeln!$A$7:$A$480,0))="","Noch zu erfassen",INDEX(Feiertagsregeln!$G$7:$G$480,MATCH($K7,Feiertagsregeln!$A$7:$A$480,0))) -> Noch zu erfassen | I7: =INDEX(Feiertagsregeln!$H$7:$H$480,MATCH($K7,Feiertagsregeln!$A$7:$A$480,0)) -> publicHoliday | J7: =INDEX(Feiertagsregeln!$R$7:$R$96,MATCH($K7,Feiertagsregeln!$A$7:$A$96,0)) -> approved | K7: CH-CAL-HOL-NATIONAL-DAY | L7: =INDEX(Feiertagsregeln!$Y$7:$Y$480,MATCH($K7,Feiertagsregeln!$A$7:$A$480,0)) -> SRC-BUNDESFEIERTAG-19940701 | M7: =INDEX(Feiertagsregeln!$Z$7:$Z$480,MATCH($K7,Feiertagsregeln!$A$7:$A$480,0)) -> Art. 1 | N7: Nur Bundesfeiertag | O7: =INDEX(Feiertagsregeln!$AA$7:$AA$480,MATCH($K7,Feiertagsregeln!$A$7:$A$480,0)) -> Ganztägig
A8: =INDEX(Feiertagsregeln!$X$7:$X$480,MATCH($K8,Feiertagsregeln!$A$7:$A$480,0)) -> 46966 | B8: =IF(ISNUMBER(A8),CHOOSE(WEEKDAY(A8,2),"Montag","Dienstag","Mittwoch","Donnerstag","Freitag","Samstag","Sonntag")&IF(O8="Ab 12.00 Uhr",", ab 12.00 Uhr",""),"n.a.") -> Dienstag | C8: CH-BE | D8: Kanton Bern | E8: =INDEX(Feiertagsregeln!$D$7:$D$480,MATCH($K8,Feiertagsregeln!$A$7:$A$480,0)) -> Bundesfeiertag | F8: =INDEX(Feiertagsregeln!$E$7:$E$480,MATCH($K8,Feiertagsregeln!$A$7:$A$480,0)) -> Fête nationale | G8: =IF(INDEX(Feiertagsregeln!$F$7:$F$480,MATCH($K8,Feiertagsregeln!$A$7:$A$480,0))="","Noch zu erfassen",INDEX(Feiertagsregeln!$F$7:$F$480,MATCH($K8,Feiertagsregeln!$A$7:$A$480,0))) -> Noch zu erfassen | H8: =IF(INDEX(Feiertagsregeln!$G$7:$G$480,MATCH($K8,Feiertagsregeln!$A$7:$A$480,0))="","Noch zu erfassen",INDEX(Feiertagsregeln!$G$7:$G$480,MATCH($K8,Feiertagsregeln!$A$7:$A$480,0))) -> Noch zu erfassen | I8: =INDEX(Feiertagsregeln!$H$7:$H$480,MATCH($K8,Feiertagsregeln!$A$7:$A$480,0)) -> publicHoliday | J8: =INDEX(Feiertagsregeln!$R$7:$R$96,MATCH($K8,Feiertagsregeln!$A$7:$A$96,0)) -> approved | K8: CH-CAL-HOL-NATIONAL-DAY | L8: =INDEX(Feiertagsregeln!$Y$7:$Y$480,MATCH($K8,Feiertagsregeln!$A$7:$A$480,0)) -> SRC-BUNDESFEIERTAG-19940701 | M8: =INDEX(Feiertagsregeln!$Z$7:$Z$480,MATCH($K8,Feiertagsregeln!$A$7:$A$480,0)) -> Art. 1 | N8: Referenzbestand | O8: =INDEX(Feiertagsregeln!$AA$7:$AA$480,MATCH($K8,Feiertagsregeln!$A$7:$A$480,0)) -> Ganztägig
A9: =INDEX(Feiertagsregeln!$X$7:$X$480,MATCH($K9,Feiertagsregeln!$A$7:$A$480,0)) -> 46753 | B9: =IF(ISNUMBER(A9),CHOOSE(WEEKDAY(A9,2),"Montag","Dienstag","Mittwoch","Donnerstag","Freitag","Samstag","Sonntag")&IF(O9="Ab 12.00 Uhr",", ab 12.00 Uhr",""),"n.a.") -> Samstag | C9: CH-BE | D9: Kanton Bern | E9: =INDEX(Feiertagsregeln!$D$7:$D$480,MATCH($K9,Feiertagsregeln!$A$7:$A$480,0)) -> Neujahr | F9: =INDEX(Feiertagsregeln!$E$7:$E$480,MATCH($K9,Feiertagsregeln!$A$7:$A$480,0)) -> Nouvel An | G9: =IF(INDEX(Feiertagsregeln!$F$7:$F$480,MATCH($K9,Feiertagsregeln!$A$7:$A$480,0))="","Noch zu erfassen",INDEX(Feiertagsregeln!$F$7:$F$480,MATCH($K9,Feiertagsregeln!$A$7:$A$480,0))) -> Noch zu erfassen | H9: =IF(INDEX(Feiertagsregeln!$G$7:$G$480,MATCH($K9,Feiertagsregeln!$A$7:$A$480,0))="","Noch zu erfassen",INDEX(Feiertagsregeln!$G$7:$G$480,MATCH($K9,Feiertagsregeln!$A$7:$A$480,0))) -> Noch zu erfassen | I9: =INDEX(Feiertagsregeln!$H$7:$H$480,MATCH($K9,Feiertagsregeln!$A$7:$A$480,0)) -> publicHoliday | J9: =INDEX(Feiertagsregeln!$R$7:$R$96,MATCH($K9,Feiertagsregeln!$A$7:$A$96,0)) -> approved | K9: BE-CAL-HOL-NEW-YEAR | L9: =INDEX(Feiertagsregeln!$Y$7:$Y$480,MATCH($K9,Feiertagsregeln!$A$7:$A$480,0)) -> SRC-FRG-BE-20210401 | M9: =INDEX(Feiertagsregeln!$Z$7:$Z$480,MATCH($K9,Feiertagsregeln!$A$7:$A$480,0)) -> Art. 2 Abs. 1 Bst. c | N9: Referenzbestand | O9: =INDEX(Feiertagsregeln!$AA$7:$AA$480,MATCH($K9,Feiertagsregeln!$A$7:$A$480,0)) -> Ganztägig
A10: =INDEX(Feiertagsregeln!$X$7:$X$480,MATCH($K10,Feiertagsregeln!$A$7:$A$480,0)) -> 46754 | B10: =IF(ISNUMBER(A10),CHOOSE(WEEKDAY(A10,2),"Montag","Dienstag","Mittwoch","Donnerstag","Freitag","Samstag","Sonntag")&IF(O10="Ab 12.00 Uhr",", ab 12.00 Uhr",""),"n.a.") -> Sonntag | C10: CH-BE | D10: Kanton Bern | E10: =INDEX(Feiertagsregeln!$D$7:$D$480,MATCH($K10,Feiertagsregeln!$A$7:$A$480,0)) -> Berchtoldstag | F10: =INDEX(Feiertagsregeln!$E$7:$E$480,MATCH($K10,Feiertagsregeln!$A$7:$A$480,0)) -> Saint-Berchtold | G10: =IF(INDEX(Feiertagsregeln!$F$7:$F$480,MATCH($K10,Feiertagsregeln!$A$7:$A$480,0))="","Noch zu erfassen",INDEX(Feiertagsregeln!$F$7:$F$480,MATCH($K10,Feiertagsregeln!$A$7:$A$480,0))) -> Noch zu erfassen | H10: =IF(INDEX(Feiertagsregeln!$G$7:$G$480,MATCH($K10,Feiertagsregeln!$A$7:$A$480,0))="","Noch zu erfassen",INDEX(Feiertagsregeln!$G$7:$G$480,MATCH($K10,Feiertagsregeln!$A$7:$A$480,0))) -> Noch zu erfassen | I10: =INDEX(Feiertagsregeln!$H$7:$H$480,MATCH($K10,Feiertagsregeln!$A$7:$A$480,0)) -> publicHoliday | J10: =INDEX(Feiertagsregeln!$R$7:$R$96,MATCH($K10,Feiertagsregeln!$A$7:$A$96,0)) -> approved | K10: BE-CAL-HOL-BERCHTOLD-DAY | L10: =INDEX(Feiertagsregeln!$Y$7:$Y$480,MATCH($K10,Feiertagsregeln!$A$7:$A$480,0)) -> SRC-FRG-BE-20210401 | M10: =INDEX(Feiertagsregeln!$Z$7:$Z$480,MATCH($K10,Feiertagsregeln!$A$7:$A$480,0)) -> Art. 2 Abs. 1 Bst. c | N10: Referenzbestand | O10: =INDEX(Feiertagsregeln!$AA$7:$AA$480,MATCH($K10,Feiertagsregeln!$A$7:$A$480,0)) -> Ganztägig
A11: =INDEX(Feiertagsregeln!$X$7:$X$480,MATCH($K11,Feiertagsregeln!$A$7:$A$480,0)) -> 46857 | B11: =IF(ISNUMBER(A11),CHOOSE(WEEKDAY(A11,2),"Montag","Dienstag","Mittwoch","Donnerstag","Freitag","Samstag","Sonntag")&IF(O11="Ab 12.00 Uhr",", ab 12.00 Uhr",""),"n.a.") -> Freitag | C11: CH-BE | D11: Kanton Bern | E11: =INDEX(Feiertagsregeln!$D$7:$D$480,MATCH($K11,Feiertagsregeln!$A$7:$A$480,0)) -> Karfreitag | F11: =INDEX(Feiertagsregeln!$E$7:$E$480,MATCH($K11,Feiertagsregeln!$A$7:$A$480,0)) -> Vendredi saint | G11: =IF(INDEX(Feiertagsregeln!$F$7:$F$480,MATCH($K11,Feiertagsregeln!$A$7:$A$480,0))="","Noch zu erfassen",INDEX(Feiertagsregeln!$F$7:$F$480,MATCH($K11,Feiertagsregeln!$A$7:$A$480,0))) -> Noch zu erfassen | H11: =IF(INDEX(Feiertagsregeln!$G$7:$G$480,MATCH($K11,Feiertagsregeln!$A$7:$A$480,0))="","Noch zu erfassen",INDEX(Feiertagsregeln!$G$7:$G$480,MATCH($K11,Feiertagsregeln!$A$7:$A$480,0))) -> Noch zu erfassen | I11: =INDEX(Feiertagsregeln!$H$7:$H$480,MATCH($K11,Feiertagsregeln!$A$7:$A$480,0)) -> publicHoliday | J11: =INDEX(Feiertagsregeln!$R$7:$R$96,MATCH($K11,Feiertagsregeln!$A$7:$A$96,0)) -> approved | K11: BE-CAL-HOL-GOOD-FRIDAY | L11: =INDEX(Feiertagsregeln!$Y$7:$Y$480,MATCH($K11,Feiertagsregeln!$A$7:$A$480,0)) -> SRC-FRG-BE-20210401 | M11: =INDEX(Feiertagsregeln!$Z$7:$Z$480,MATCH($K11,Feiertagsregeln!$A$7:$A$480,0)) -> Art. 2 Abs. 1 Bst. b | N11: Referenzbestand | O11: =INDEX(Feiertagsregeln!$AA$7:$AA$480,MATCH($K11,Feiertagsregeln!$A$7:$A$480,0)) -> Ganztägig
A12: =INDEX(Feiertagsregeln!$X$7:$X$480,MATCH($K12,Feiertagsregeln!$A$7:$A$480,0)) -> 46859 | B12: =IF(ISNUMBER(A12),CHOOSE(WEEKDAY(A12,2),"Montag","Dienstag","Mittwoch","Donnerstag","Freitag","Samstag","Sonntag")&IF(O12="Ab 12.00 Uhr",", ab 12.00 Uhr",""),"n.a.") -> Sonntag | C12: CH-BE | D12: Kanton Bern | E12: =INDEX(Feiertagsregeln!$D$7:$D$480,MATCH($K12,Feiertagsregeln!$A$7:$A$480,0)) -> Ostern | F12: =INDEX(Feiertagsregeln!$E$7:$E$480,MATCH($K12,Feiertagsregeln!$A$7:$A$480,0)) -> Pâques | G12: =IF(INDEX(Feiertagsregeln!$F$7:$F$480,MATCH($K12,Feiertagsregeln!$A$7:$A$480,0))="","Noch zu erfassen",INDEX(Feiertagsregeln!$F$7:$F$480,MATCH($K12,Feiertagsregeln!$A$7:$A$480,0))) -> Noch zu erfassen | H12: =IF(INDEX(Feiertagsregeln!$G$7:$G$480,MATCH($K12,Feiertagsregeln!$A$7:$A$480,0))="","Noch zu erfassen",INDEX(Feiertagsregeln!$G$7:$G$480,MATCH($K12,Feiertagsregeln!$A$7:$A$480,0))) -> Noch zu erfassen | I12: =INDEX(Feiertagsregeln!$H$7:$H$480,MATCH($K12,Feiertagsregeln!$A$7:$A$480,0)) -> publicHoliday | J12: =INDEX(Feiertagsregeln!$R$7:$R$96,MATCH($K12,Feiertagsregeln!$A$7:$A$96,0)) -> approved | K12: BE-CAL-HOL-EASTER | L12: =INDEX(Feiertagsregeln!$Y$7:$Y$480,MATCH($K12,Feiertagsregeln!$A$7:$A$480,0)) -> SRC-FRG-BE-20210401 | M12: =INDEX(Feiertagsregeln!$Z$7:$Z$480,MATCH($K12,Feiertagsregeln!$A$7:$A$480,0)) -> Art. 2 Abs. 1 Bst. b | N12: Referenzbestand | O12: =INDEX(Feiertagsregeln!$AA$7:$AA$480,MATCH($K12,Feiertagsregeln!$A$7:$A$480,0)) -> Ganztägig
A13: =INDEX(Feiertagsregeln!$X$7:$X$480,MATCH($K13,Feiertagsregeln!$A$7:$A$480,0)) -> 46860 | B13: =IF(ISNUMBER(A13),CHOOSE(WEEKDAY(A13,2),"Montag","Dienstag","Mittwoch","Donnerstag","Freitag","Samstag","Sonntag")&IF(O13="Ab 12.00 Uhr",", ab 12.00 Uhr",""),"n.a.") -> Montag | C13: CH-BE | D13: Kanton Bern | E13: =INDEX(Feiertagsregeln!$D$7:$D$480,MATCH($K13,Feiertagsregeln!$A$7:$A$480,0)) -> Ostermontag | F13: =INDEX(Feiertagsregeln!$E$7:$E$480,MATCH($K13,Feiertagsregeln!$A$7:$A$480,0)) -> Lundi de Pâques | G13: =IF(INDEX(Feiertagsregeln!$F$7:$F$480,MATCH($K13,Feiertagsregeln!$A$7:$A$480,0))="","Noch zu erfassen",INDEX(Feiertagsregeln!$F$7:$F$480,MATCH($K13,Feiertagsregeln!$A$7:$A$480,0))) -> Noch zu erfassen | H13: =IF(INDEX(Feiertagsregeln!$G$7:$G$480,MATCH($K13,Feiertagsregeln!$A$7:$A$480,0))="","Noch zu erfassen",INDEX(Feiertagsregeln!$G$7:$G$480,MATCH($K13,Feiertagsregeln!$A$7:$A$480,0))) -> Noch zu erfassen | I13: =INDEX(Feiertagsregeln!$H$7:$H$480,MATCH($K13,Feiertagsregeln!$A$7:$A$480,0)) -> publicHoliday | J13: =INDEX(Feiertagsregeln!$R$7:$R$96,MATCH($K13,Feiertagsregeln!$A$7:$A$96,0)) -> approved | K13: BE-CAL-HOL-EASTER-MONDAY | L13: =INDEX(Feiertagsregeln!$Y$7:$Y$480,MATCH($K13,Feiertagsregeln!$A$7:$A$480,0)) -> SRC-FRG-BE-20210401 | M13: =INDEX(Feiertagsregeln!$Z$7:$Z$480,MATCH($K13,Feiertagsregeln!$A$7:$A$480,0)) -> Art. 2 Abs. 1 Bst. c | N13: Referenzbestand | O13: =INDEX(Feiertagsregeln!$AA$7:$AA$480,MATCH($K13,Feiertagsregeln!$A$7:$A$480,0)) -> Ganztägig
A14: =INDEX(Feiertagsregeln!$X$7:$X$480,MATCH($K14,Feiertagsregeln!$A$7:$A$480,0)) -> 46898 | B14: =IF(ISNUMBER(A14),CHOOSE(WEEKDAY(A14,2),"Montag","Dienstag","Mittwoch","Donnerstag","Freitag","Samstag","Sonntag")&IF(O14="Ab 12.00 Uhr",", ab 12.00 Uhr",""),"n.a.") -> Donnerstag | C14: CH-BE | D14: Kanton Bern | E14: =INDEX(Feiertagsregeln!$D$7:$D$480,MATCH($K14,Feiertagsregeln!$A$7:$A$480,0)) -> Auffahrt | F14: =INDEX(Feiertagsregeln!$E$7:$E$480,MATCH($K14,Feiertagsregeln!$A$7:$A$480,0)) -> Ascension | G14: =IF(INDEX(Feiertagsregeln!$F$7:$F$480,MATCH($K14,Feiertagsregeln!$A$7:$A$480,0))="","Noch zu erfassen",INDEX(Feiertagsregeln!$F$7:$F$480,MATCH($K14,Feiertagsregeln!$A$7:$A$480,0))) -> Noch zu erfassen | H14: =IF(INDEX(Feiertagsregeln!$G$7:$G$480,MATCH($K14,Feiertagsregeln!$A$7:$A$480,0))="","Noch zu erfassen",INDEX(Feiertagsregeln!$G$7:$G$480,MATCH($K14,Feiertagsregeln!$A$7:$A$480,0))) -> Noch zu erfassen | I14: =INDEX(Feiertagsregeln!$H$7:$H$480,MATCH($K14,Feiertagsregeln!$A$7:$A$480,0)) -> publicHoliday | J14: =INDEX(Feiertagsregeln!$R$7:$R$96,MATCH($K14,Feiertagsregeln!$A$7:$A$96,0)) -> approved | K14: BE-CAL-HOL-ASCENSION | L14: =INDEX(Feiertagsregeln!$Y$7:$Y$480,MATCH($K14,Feiertagsregeln!$A$7:$A$480,0)) -> SRC-FRG-BE-20210401 | M14: =INDEX(Feiertagsregeln!$Z$7:$Z$480,MATCH($K14,Feiertagsregeln!$A$7:$A$480,0)) -> Art. 2 Abs. 1 Bst. b | N14: Referenzbestand | O14: =INDEX(Feiertagsregeln!$AA$7:$AA$480,MATCH($K14,Feiertagsregeln!$A$7:$A$480,0)) -> Ganztägig
A15: =INDEX(Feiertagsregeln!$X$7:$X$480,MATCH($K15,Feiertagsregeln!$A$7:$A$480,0)) -> 46908 | B15: =IF(ISNUMBER(A15),CHOOSE(WEEKDAY(A15,2),"Montag","Dienstag","Mittwoch","Donnerstag","Freitag","Samstag","Sonntag")&IF(O15="Ab 12.00 Uhr",", ab 12.00 Uhr",""),"n.a.") -> Sonntag | C15: CH-BE | D15: Kanton Bern | E15: =INDEX(Feiertagsregeln!$D$7:$D$480,MATCH($K15,Feiertagsregeln!$A$7:$A$480,0)) -> Pfingsten | F15: =INDEX(Feiertagsregeln!$E$7:$E$480,MATCH($K15,Feiertagsregeln!$A$7:$A$480,0)) -> Pentecôte | G15: =IF(INDEX(Feiertagsregeln!$F$7:$F$480,MATCH($K15,Feiertagsregeln!$A$7:$A$480,0))="","Noch zu erfassen",INDEX(Feiertagsregeln!$F$7:$F$480,MATCH($K15,Feiertagsregeln!$A$7:$A$480,0))) -> Noch zu erfassen | H15: =IF(INDEX(Feiertagsregeln!$G$7:$G$480,MATCH($K15,Feiertagsregeln!$A$7:$A$480,0))="","Noch zu erfassen",INDEX(Feiertagsregeln!$G$7:$G$480,MATCH($K15,Feiertagsregeln!$A$7:$A$480,0))) -> Noch zu erfassen | I15: =INDEX(Feiertagsregeln!$H$7:$H$480,MATCH($K15,Feiertagsregeln!$A$7:$A$480,0)) -> publicHoliday | J15: =INDEX(Feiertagsregeln!$R$7:$R$96,MATCH($K15,Feiertagsregeln!$A$7:$A$96,0)) -> approved | K15: BE-CAL-HOL-PENTECOST | L15: =INDEX(Feiertagsregeln!$Y$7:$Y$480,MATCH($K15,Feiertagsregeln!$A$7:$A$480,0)) -> SRC-FRG-BE-20210401 | M15: =INDEX(Feiertagsregeln!$Z$7:$Z$480,MATCH($K15,Feiertagsregeln!$A$7:$A$480,0)) -> Art. 2 Abs. 1 Bst. b | N15: Referenzbestand | O15: =INDEX(Feiertagsregeln!$AA$7:$AA$480,MATCH($K15,Feiertagsregeln!$A$7:$A$480,0)) -> Ganztägig
A16: =INDEX(Feiertagsregeln!$X$7:$X$480,MATCH($K16,Feiertagsregeln!$A$7:$A$480,0)) -> 46909 | B16: =IF(ISNUMBER(A16),CHOOSE(WEEKDAY(A16,2),"Montag","Dienstag","Mittwoch","Donnerstag","Freitag","Samstag","Sonntag")&IF(O16="Ab 12.00 Uhr",", ab 12.00 Uhr",""),"n.a.") -> Montag | C16: CH-BE | D16: Kanton Bern | E16: =INDEX(Feiertagsregeln!$D$7:$D$480,MATCH($K16,Feiertagsregeln!$A$7:$A$480,0)) -> Pfingstmontag | F16: =INDEX(Feiertagsregeln!$E$7:$E$480,MATCH($K16,Feiertagsregeln!$A$7:$A$480,0)) -> Lundi de Pentecôte | G16: =IF(INDEX(Feiertagsregeln!$F$7:$F$480,MATCH($K16,Feiertagsregeln!$A$7:$A$480,0))="","Noch zu erfassen",INDEX(Feiertagsregeln!$F$7:$F$480,MATCH($K16,Feiertagsregeln!$A$7:$A$480,0))) -> Noch zu erfassen | H16: =IF(INDEX(Feiertagsregeln!$G$7:$G$480,MATCH($K16,Feiertagsregeln!$A$7:$A$480,0))="","Noch zu erfassen",INDEX(Feiertagsregeln!$G$7:$G$480,MATCH($K16,Feiertagsregeln!$A$7:$A$480,0))) -> Noch zu erfassen | I16: =INDEX(Feiertagsregeln!$H$7:$H$480,MATCH($K16,Feiertagsregeln!$A$7:$A$480,0)) -> publicHoliday | J16: =INDEX(Feiertagsregeln!$R$7:$R$96,MATCH($K16,Feiertagsregeln!$A$7:$A$96,0)) -> approved | K16: BE-CAL-HOL-WHIT-MONDAY | L16: =INDEX(Feiertagsregeln!$Y$7:$Y$480,MATCH($K16,Feiertagsregeln!$A$7:$A$480,0)) -> SRC-FRG-BE-20210401 | M16: =INDEX(Feiertagsregeln!$Z$7:$Z$480,MATCH($K16,Feiertagsregeln!$A$7:$A$480,0)) -> Art. 2 Abs. 1 Bst. c | N16: Referenzbestand | O16: =INDEX(Feiertagsregeln!$AA$7:$AA$480,MATCH($K16,Feiertagsregeln!$A$7:$A$480,0)) -> Ganztägig
A17: =INDEX(Feiertagsregeln!$X$7:$X$480,MATCH($K17,Feiertagsregeln!$A$7:$A$480,0)) -> 47013 | B17: =IF(ISNUMBER(A17),CHOOSE(WEEKDAY(A17,2),"Montag","Dienstag","Mittwoch","Donnerstag","Freitag","Samstag","Sonntag")&IF(O17="Ab 12.00 Uhr",", ab 12.00 Uhr",""),"n.a.") -> Sonntag | C17: CH-BE | D17: Kanton Bern | E17: =INDEX(Feiertagsregeln!$D$7:$D$480,MATCH($K17,Feiertagsregeln!$A$7:$A$480,0)) -> Eidgenössischer Dank-, Buss- und Bettag | F17: =INDEX(Feiertagsregeln!$E$7:$E$480,MATCH($K17,Feiertagsregeln!$A$7:$A$480,0)) -> Jeûne fédéral | G17: =IF(INDEX(Feiertagsregeln!$F$7:$F$480,MATCH($K17,Feiertagsregeln!$A$7:$A$480,0))="","Noch zu erfassen",INDEX(Feiertagsregeln!$F$7:$F$480,MATCH($K17,Feiertagsregeln!$A$7:$A$480,0))) -> Noch zu erfassen | H17: =IF(INDEX(Feiertagsregeln!$G$7:$G$480,MATCH($K17,Feiertagsregeln!$A$7:$A$480,0))="","Noch zu erfassen",INDEX(Feiertagsregeln!$G$7:$G$480,MATCH($K17,Feiertagsregeln!$A$7:$A$480,0))) -> Noch zu erfassen | I17: =INDEX(Feiertagsregeln!$H$7:$H$480,MATCH($K17,Feiertagsregeln!$A$7:$A$480,0)) -> publicHoliday | J17: =INDEX(Feiertagsregeln!$R$7:$R$96,MATCH($K17,Feiertagsregeln!$A$7:$A$96,0)) -> approved | K17: BE-CAL-HOL-FEDERAL-FAST | L17: =INDEX(Feiertagsregeln!$Y$7:$Y$480,MATCH($K17,Feiertagsregeln!$A$7:$A$480,0)) -> SRC-FRG-BE-20210401 | M17: =INDEX(Feiertagsregeln!$Z$7:$Z$480,MATCH($K17,Feiertagsregeln!$A$7:$A$480,0)) -> Art. 2 Abs. 1 Bst. b | N17: Referenzbestand | O17: =INDEX(Feiertagsregeln!$AA$7:$AA$480,MATCH($K17,Feiertagsregeln!$A$7:$A$480,0)) -> Ganztägig
A18: =INDEX(Feiertagsregeln!$X$7:$X$480,MATCH($K18,Feiertagsregeln!$A$7:$A$480,0)) -> 47112 | B18: =IF(ISNUMBER(A18),CHOOSE(WEEKDAY(A18,2),"Montag","Dienstag","Mittwoch","Donnerstag","Freitag","Samstag","Sonntag")&IF(O18="Ab 12.00 Uhr",", ab 12.00 Uhr",""),"n.a.") -> Montag | C18: CH-BE | D18: Kanton Bern | E18: =INDEX(Feiertagsregeln!$D$7:$D$480,MATCH($K18,Feiertagsregeln!$A$7:$A$480,0)) -> Weihnachten | F18: =INDEX(Feiertagsregeln!$E$7:$E$480,MATCH($K18,Feiertagsregeln!$A$7:$A$480,0)) -> Noël | G18: =IF(INDEX(Feiertagsregeln!$F$7:$F$480,MATCH($K18,Feiertagsregeln!$A$7:$A$480,0))="","Noch zu erfassen",INDEX(Feiertagsregeln!$F$7:$F$480,MATCH($K18,Feiertagsregeln!$A$7:$A$480,0))) -> Noch zu erfassen | H18: =IF(INDEX(Feiertagsregeln!$G$7:$G$480,MATCH($K18,Feiertagsregeln!$A$7:$A$480,0))="","Noch zu erfassen",INDEX(Feiertagsregeln!$G$7:$G$480,MATCH($K18,Feiertagsregeln!$A$7:$A$480,0))) -> Noch zu erfassen | I18: =INDEX(Feiertagsregeln!$H$7:$H$480,MATCH($K18,Feiertagsregeln!$A$7:$A$480,0)) -> publicHoliday | J18: =INDEX(Feiertagsregeln!$R$7:$R$96,MATCH($K18,Feiertagsregeln!$A$7:$A$96,0)) -> approved | K18: BE-CAL-HOL-CHRISTMAS | L18: =INDEX(Feiertagsregeln!$Y$7:$Y$480,MATCH($K18,Feiertagsregeln!$A$7:$A$480,0)) -> SRC-FRG-BE-20210401 | M18: =INDEX(Feiertagsregeln!$Z$7:$Z$480,MATCH($K18,Feiertagsregeln!$A$7:$A$480,0)) -> Art. 2 Abs. 1 Bst. b | N18: Referenzbestand | O18: =INDEX(Feiertagsregeln!$AA$7:$AA$480,MATCH($K18,Feiertagsregeln!$A$7:$A$480,0)) -> Ganztägig
A19: =INDEX(Feiertagsregeln!$X$7:$X$480,MATCH($K19,Feiertagsregeln!$A$7:$A$480,0)) -> 47113 | B19: =IF(ISNUMBER(A19),CHOOSE(WEEKDAY(A19,2),"Montag","Dienstag","Mittwoch","Donnerstag","Freitag","Samstag","Sonntag")&IF(O19="Ab 12.00 Uhr",", ab 12.00 Uhr",""),"n.a.") -> Dienstag | C19: CH-BE | D19: Kanton Bern | E19: =INDEX(Feiertagsregeln!$D$7:$D$480,MATCH($K19,Feiertagsregeln!$A$7:$A$480,0)) -> Stephanstag | F19: =INDEX(Feiertagsregeln!$E$7:$E$480,MATCH($K19,Feiertagsregeln!$A$7:$A$480,0)) -> Saint-Étienne | G19: =IF(INDEX(Feiertagsregeln!$F$7:$F$480,MATCH($K19,Feiertagsregeln!$A$7:$A$480,0))="","Noch zu erfassen",INDEX(Feiertagsregeln!$F$7:$F$480,MATCH($K19,Feiertagsregeln!$A$7:$A$480,0))) -> Noch zu erfassen | H19: =IF(INDEX(Feiertagsregeln!$G$7:$G$480,MATCH($K19,Feiertagsregeln!$A$7:$A$480,0))="","Noch zu erfassen",INDEX(Feiertagsregeln!$G$7:$G$480,MATCH($K19,Feiertagsregeln!$A$7:$A$480,0))) -> Noch zu erfassen | I19: =INDEX(Feiertagsregeln!$H$7:$H$480,MATCH($K19,Feiertagsregeln!$A$7:$A$480,0)) -> publicHoliday | J19: =INDEX(Feiertagsregeln!$R$7:$R$96,MATCH($K19,Feiertagsregeln!$A$7:$A$96,0)) -> approved | K19: BE-CAL-HOL-ST-STEPHEN | L19: =INDEX(Feiertagsregeln!$Y$7:$Y$480,MATCH($K19,Feiertagsregeln!$A$7:$A$480,0)) -> SRC-FRG-BE-20210401 | M19: =INDEX(Feiertagsregeln!$Z$7:$Z$480,MATCH($K19,Feiertagsregeln!$A$7:$A$480,0)) -> Art. 2 Abs. 1 Bst. c | N19: Referenzbestand | O19: =INDEX(Feiertagsregeln!$AA$7:$AA$480,MATCH($K19,Feiertagsregeln!$A$7:$A$480,0)) -> Ganztägig
A20: =INDEX(Feiertagsregeln!$X$7:$X$480,MATCH($K20,Feiertagsregeln!$A$7:$A$480,0)) -> 46919 | B20: =IF(ISNUMBER(A20),CHOOSE(WEEKDAY(A20,2),"Montag","Dienstag","Mittwoch","Donnerstag","Freitag","Samstag","Sonntag")&IF(O20="Ab 12.00 Uhr",", ab 12.00 Uhr",""),"n.a.") -> Donnerstag | C20: CH-AG | D20: Bezirk Baden ohne Bergdietikon | E20: =INDEX(Feiertagsregeln!$D$7:$D$480,MATCH($K20,Feiertagsregeln!$A$7:$A$480,0)) -> Fronleichnam | F20: =INDEX(Feiertagsregeln!$E$7:$E$480,MATCH($K20,Feiertagsregeln!$A$7:$A$480,0)) -> Fête-Dieu | G20: =IF(INDEX(Feiertagsregeln!$F$7:$F$480,MATCH($K20,Feiertagsregeln!$A$7:$A$480,0))="","Noch zu erfassen",INDEX(Feiertagsregeln!$F$7:$F$480,MATCH($K20,Feiertagsregeln!$A$7:$A$480,0))) -> Noch zu erfassen | H20: =IF(INDEX(Feiertagsregeln!$G$7:$G$480,MATCH($K20,Feiertagsregeln!$A$7:$A$480,0))="","Noch zu erfassen",INDEX(Feiertagsregeln!$G$7:$G$480,MATCH($K20,Feiertagsregeln!$A$7:$A$480,0))) -> Noch zu erfassen | I20: =INDEX(Feiertagsregeln!$H$7:$H$480,MATCH($K20,Feiertagsregeln!$A$7:$A$480,0)) -> labourLawHoliday | J20: open | K20: AG-WORK-HOL-CORPUS-CHRISTI | L20: =INDEX(Feiertagsregeln!$Y$7:$Y$480,MATCH($K20,Feiertagsregeln!$A$7:$A$480,0)) -> SRC-AG-EGARR-20250901 | M20: =INDEX(Feiertagsregeln!$Z$7:$Z$480,MATCH($K20,Feiertagsregeln!$A$7:$A$480,0)) -> § 6 Abs. 1 Bst. b Ziff. 2 | N20: Normliste erfasst, Fachfreigabe offen | O20: =INDEX(Feiertagsregeln!$AA$7:$AA$480,MATCH($K20,Feiertagsregeln!$A$7:$A$480,0)) -> Ganztägig
A21: =INDEX(Feiertagsregeln!$X$7:$X$480,MATCH($K21,Feiertagsregeln!$A$7:$A$480,0)) -> 46754 | B21: =IF(ISNUMBER(A21),CHOOSE(WEEKDAY(A21,2),"Montag","Dienstag","Mittwoch","Donnerstag","Freitag","Samstag","Sonntag")&IF(O21="Ab 12.00 Uhr",", ab 12.00 Uhr",""),"n.a.") -> Sonntag | C21: CH-AG | D21: Gemeinde Bergdietikon | E21: =INDEX(Feiertagsregeln!$D$7:$D$480,MATCH($K21,Feiertagsregeln!$A$7:$A$480,0)) -> Berchtoldstag | F21: =INDEX(Feiertagsregeln!$E$7:$E$480,MATCH($K21,Feiertagsregeln!$A$7:$A$480,0)) -> Saint-Berchtold | G21: =IF(INDEX(Feiertagsregeln!$F$7:$F$480,MATCH($K21,Feiertagsregeln!$A$7:$A$480,0))="","Noch zu erfassen",INDEX(Feiertagsregeln!$F$7:$F$480,MATCH($K21,Feiertagsregeln!$A$7:$A$480,0))) -> Noch zu erfassen | H21: =IF(INDEX(Feiertagsregeln!$G$7:$G$480,MATCH($K21,Feiertagsregeln!$A$7:$A$480,0))="","Noch zu erfassen",INDEX(Feiertagsregeln!$G$7:$G$480,MATCH($K21,Feiertagsregeln!$A$7:$A$480,0))) -> Noch zu erfassen | I21: =INDEX(Feiertagsregeln!$H$7:$H$480,MATCH($K21,Feiertagsregeln!$A$7:$A$480,0)) -> labourLawHoliday | J21: open | K21: AG-WORK-HOL-BERCHTOLD | L21: =INDEX(Feiertagsregeln!$Y$7:$Y$480,MATCH($K21,Feiertagsregeln!$A$7:$A$480,0)) -> SRC-AG-EGARR-20250901 | M21: =INDEX(Feiertagsregeln!$Z$7:$Z$480,MATCH($K21,Feiertagsregeln!$A$7:$A$480,0)) -> § 6 Abs. 1 Bst. b Ziff. 1 | N21: Normliste erfasst, Fachfreigabe offen | O21: =INDEX(Feiertagsregeln!$AA$7:$AA$480,MATCH($K21,Feiertagsregeln!$A$7:$A$480,0)) -> Ganztägig
A22: =INDEX(Feiertagsregeln!$X$7:$X$480,MATCH($K22,Feiertagsregeln!$A$7:$A$480,0)) -> 47058 | B22: =IF(ISNUMBER(A22),CHOOSE(WEEKDAY(A22,2),"Montag","Dienstag","Mittwoch","Donnerstag","Freitag","Samstag","Sonntag")&IF(O22="Ab 12.00 Uhr",", ab 12.00 Uhr",""),"n.a.") -> Mittwoch | C22: CH-AG | D22: Aargau, prozessuale Zuordnung | E22: =INDEX(Feiertagsregeln!$D$7:$D$480,MATCH($K22,Feiertagsregeln!$A$7:$A$480,0)) -> Allerheiligen | F22: =INDEX(Feiertagsregeln!$E$7:$E$480,MATCH($K22,Feiertagsregeln!$A$7:$A$480,0)) -> Toussaint | G22: =IF(INDEX(Feiertagsregeln!$F$7:$F$480,MATCH($K22,Feiertagsregeln!$A$7:$A$480,0))="","Noch zu erfassen",INDEX(Feiertagsregeln!$F$7:$F$480,MATCH($K22,Feiertagsregeln!$A$7:$A$480,0))) -> Noch zu erfassen | H22: =IF(INDEX(Feiertagsregeln!$G$7:$G$480,MATCH($K22,Feiertagsregeln!$A$7:$A$480,0))="","Noch zu erfassen",INDEX(Feiertagsregeln!$G$7:$G$480,MATCH($K22,Feiertagsregeln!$A$7:$A$480,0))) -> Noch zu erfassen | I22: =INDEX(Feiertagsregeln!$H$7:$H$480,MATCH($K22,Feiertagsregeln!$A$7:$A$480,0)) -> proceduralEquivalentDay | J22: open | K22: AG-PROC-DAY-ALL-SAINTS | L22: =INDEX(Feiertagsregeln!$Y$7:$Y$480,MATCH($K22,Feiertagsregeln!$A$7:$A$480,0)) -> SRC-AG-EGZPO | M22: =INDEX(Feiertagsregeln!$Z$7:$Z$480,MATCH($K22,Feiertagsregeln!$A$7:$A$480,0)) -> § 21 | N22: Normliste erfasst, Fachfreigabe offen | O22: =INDEX(Feiertagsregeln!$AA$7:$AA$480,MATCH($K22,Feiertagsregeln!$A$7:$A$480,0)) -> Ganztägig
A23: =INDEX(Feiertagsregeln!$X$7:$X$480,MATCH($K23,Feiertagsregeln!$A$7:$A$480,0)) -> 46753 | B23: =IF(ISNUMBER(A23),CHOOSE(WEEKDAY(A23,2),"Montag","Dienstag","Mittwoch","Donnerstag","Freitag","Samstag","Sonntag")&IF(O23="Ab 12.00 Uhr",", ab 12.00 Uhr",""),"n.a.") -> Samstag | C23: CH-AG | D23: Bezirke Aarau, Brugg, Kulm, Lenzburg und Zofingen | E23: =INDEX(Feiertagsregeln!$D$7:$D$480,MATCH($K23,Feiertagsregeln!$A$7:$A$480,0)) -> Neujahr | F23: =INDEX(Feiertagsregeln!$E$7:$E$480,MATCH($K23,Feiertagsregeln!$A$7:$A$480,0)) -> Nouvel An | G23: =IF(INDEX(Feiertagsregeln!$F$7:$F$480,MATCH($K23,Feiertagsregeln!$A$7:$A$480,0))="","Noch zu erfassen",INDEX(Feiertagsregeln!$F$7:$F$480,MATCH($K23,Feiertagsregeln!$A$7:$A$480,0))) -> Noch zu erfassen | H23: =IF(INDEX(Feiertagsregeln!$G$7:$G$480,MATCH($K23,Feiertagsregeln!$A$7:$A$480,0))="","Noch zu erfassen",INDEX(Feiertagsregeln!$G$7:$G$480,MATCH($K23,Feiertagsregeln!$A$7:$A$480,0))) -> Noch zu erfassen | I23: =INDEX(Feiertagsregeln!$H$7:$H$480,MATCH($K23,Feiertagsregeln!$A$7:$A$480,0)) -> labourLawHoliday | J23: open | K23: AG-WORK-HOL-A-NEW-YEAR | L23: =INDEX(Feiertagsregeln!$Y$7:$Y$480,MATCH($K23,Feiertagsregeln!$A$7:$A$480,0)) -> SRC-AG-EGARR-20250901 | M23: =INDEX(Feiertagsregeln!$Z$7:$Z$480,MATCH($K23,Feiertagsregeln!$A$7:$A$480,0)) -> § 6 Abs. 1 Bst. a | N23: Normliste erfasst, Fachfreigabe offen | O23: =INDEX(Feiertagsregeln!$AA$7:$AA$480,MATCH($K23,Feiertagsregeln!$A$7:$A$480,0)) -> Ganztägig
A24: =INDEX(Feiertagsregeln!$X$7:$X$480,MATCH($K24,Feiertagsregeln!$A$7:$A$480,0)) -> 46754 | B24: =IF(ISNUMBER(A24),CHOOSE(WEEKDAY(A24,2),"Montag","Dienstag","Mittwoch","Donnerstag","Freitag","Samstag","Sonntag")&IF(O24="Ab 12.00 Uhr",", ab 12.00 Uhr",""),"n.a.") -> Sonntag | C24: CH-AG | D24: Bezirke Aarau, Brugg, Kulm, Lenzburg und Zofingen | E24: =INDEX(Feiertagsregeln!$D$7:$D$480,MATCH($K24,Feiertagsregeln!$A$7:$A$480,0)) -> Berchtoldstag | F24: =INDEX(Feiertagsregeln!$E$7:$E$480,MATCH($K24,Feiertagsregeln!$A$7:$A$480,0)) -> Saint-Berchtold | G24: =IF(INDEX(Feiertagsregeln!$F$7:$F$480,MATCH($K24,Feiertagsregeln!$A$7:$A$480,0))="","Noch zu erfassen",INDEX(Feiertagsregeln!$F$7:$F$480,MATCH($K24,Feiertagsregeln!$A$7:$A$480,0))) -> Noch zu erfassen | H24: =IF(INDEX(Feiertagsregeln!$G$7:$G$480,MATCH($K24,Feiertagsregeln!$A$7:$A$480,0))="","Noch zu erfassen",INDEX(Feiertagsregeln!$G$7:$G$480,MATCH($K24,Feiertagsregeln!$A$7:$A$480,0))) -> Noch zu erfassen | I24: =INDEX(Feiertagsregeln!$H$7:$H$480,MATCH($K24,Feiertagsregeln!$A$7:$A$480,0)) -> labourLawHoliday | J24: open | K24: AG-WORK-HOL-A-BERCHTOLD | L24: =INDEX(Feiertagsregeln!$Y$7:$Y$480,MATCH($K24,Feiertagsregeln!$A$7:$A$480,0)) -> SRC-AG-EGARR-20250901 | M24: =INDEX(Feiertagsregeln!$Z$7:$Z$480,MATCH($K24,Feiertagsregeln!$A$7:$A$480,0)) -> § 6 Abs. 1 Bst. a | N24: Normliste erfasst, Fachfreigabe offen | O24: =INDEX(Feiertagsregeln!$AA$7:$AA$480,MATCH($K24,Feiertagsregeln!$A$7:$A$480,0)) -> Ganztägig
A25: =INDEX(Feiertagsregeln!$X$7:$X$480,MATCH($K25,Feiertagsregeln!$A$7:$A$480,0)) -> 46857 | B25: =IF(ISNUMBER(A25),CHOOSE(WEEKDAY(A25,2),"Montag","Dienstag","Mittwoch","Donnerstag","Freitag","Samstag","Sonntag")&IF(O25="Ab 12.00 Uhr",", ab 12.00 Uhr",""),"n.a.") -> Freitag | C25: CH-AG | D25: Bezirke Aarau, Brugg, Kulm, Lenzburg und Zofingen | E25: =INDEX(Feiertagsregeln!$D$7:$D$480,MATCH($K25,Feiertagsregeln!$A$7:$A$480,0)) -> Karfreitag | F25: =INDEX(Feiertagsregeln!$E$7:$E$480,MATCH($K25,Feiertagsregeln!$A$7:$A$480,0)) -> Vendredi saint | G25: =IF(INDEX(Feiertagsregeln!$F$7:$F$480,MATCH($K25,Feiertagsregeln!$A$7:$A$480,0))="","Noch zu erfassen",INDEX(Feiertagsregeln!$F$7:$F$480,MATCH($K25,Feiertagsregeln!$A$7:$A$480,0))) -> Noch zu erfassen | H25: =IF(INDEX(Feiertagsregeln!$G$7:$G$480,MATCH($K25,Feiertagsregeln!$A$7:$A$480,0))="","Noch zu erfassen",INDEX(Feiertagsregeln!$G$7:$G$480,MATCH($K25,Feiertagsregeln!$A$7:$A$480,0))) -> Noch zu erfassen | I25: =INDEX(Feiertagsregeln!$H$7:$H$480,MATCH($K25,Feiertagsregeln!$A$7:$A$480,0)) -> labourLawHoliday | J25: open | K25: AG-WORK-HOL-A-GOOD-FRIDAY | L25: =INDEX(Feiertagsregeln!$Y$7:$Y$480,MATCH($K25,Feiertagsregeln!$A$7:$A$480,0)) -> SRC-AG-EGARR-20250901 | M25: =INDEX(Feiertagsregeln!$Z$7:$Z$480,MATCH($K25,Feiertagsregeln!$A$7:$A$480,0)) -> § 6 Abs. 1 Bst. a | N25: Normliste erfasst, Fachfreigabe offen | O25: =INDEX(Feiertagsregeln!$AA$7:$AA$480,MATCH($K25,Feiertagsregeln!$A$7:$A$480,0)) -> Ganztägig
A26: =INDEX(Feiertagsregeln!$X$7:$X$480,MATCH($K26,Feiertagsregeln!$A$7:$A$480,0)) -> 46860 | B26: =IF(ISNUMBER(A26),CHOOSE(WEEKDAY(A26,2),"Montag","Dienstag","Mittwoch","Donnerstag","Freitag","Samstag","Sonntag")&IF(O26="Ab 12.00 Uhr",", ab 12.00 Uhr",""),"n.a.") -> Montag | C26: CH-AG | D26: Bezirke Aarau, Brugg, Kulm, Lenzburg und Zofingen | E26: =INDEX(Feiertagsregeln!$D$7:$D$480,MATCH($K26,Feiertagsregeln!$A$7:$A$480,0)) -> Ostermontag | F26: =INDEX(Feiertagsregeln!$E$7:$E$480,MATCH($K26,Feiertagsregeln!$A$7:$A$480,0)) -> Lundi de Pâques | G26: =IF(INDEX(Feiertagsregeln!$F$7:$F$480,MATCH($K26,Feiertagsregeln!$A$7:$A$480,0))="","Noch zu erfassen",INDEX(Feiertagsregeln!$F$7:$F$480,MATCH($K26,Feiertagsregeln!$A$7:$A$480,0))) -> Noch zu erfassen | H26: =IF(INDEX(Feiertagsregeln!$G$7:$G$480,MATCH($K26,Feiertagsregeln!$A$7:$A$480,0))="","Noch zu erfassen",INDEX(Feiertagsregeln!$G$7:$G$480,MATCH($K26,Feiertagsregeln!$A$7:$A$480,0))) -> Noch zu erfassen | I26: =INDEX(Feiertagsregeln!$H$7:$H$480,MATCH($K26,Feiertagsregeln!$A$7:$A$480,0)) -> labourLawHoliday | J26: open | K26: AG-WORK-HOL-A-EASTER-MONDAY | L26: =INDEX(Feiertagsregeln!$Y$7:$Y$480,MATCH($K26,Feiertagsregeln!$A$7:$A$480,0)) -> SRC-AG-EGARR-20250901 | M26: =INDEX(Feiertagsregeln!$Z$7:$Z$480,MATCH($K26,Feiertagsregeln!$A$7:$A$480,0)) -> § 6 Abs. 1 Bst. a | N26: Normliste erfasst, Fachfreigabe offen | O26: =INDEX(Feiertagsregeln!$AA$7:$AA$480,MATCH($K26,Feiertagsregeln!$A$7:$A$480,0)) -> Ganztägig
A27: =INDEX(Feiertagsregeln!$X$7:$X$480,MATCH($K27,Feiertagsregeln!$A$7:$A$480,0)) -> 46898 | B27: =IF(ISNUMBER(A27),CHOOSE(WEEKDAY(A27,2),"Montag","Dienstag","Mittwoch","Donnerstag","Freitag","Samstag","Sonntag")&IF(O27="Ab 12.00 Uhr",", ab 12.00 Uhr",""),"n.a.") -> Donnerstag | C27: CH-AG | D27: Bezirke Aarau, Brugg, Kulm, Lenzburg und Zofingen | E27: =INDEX(Feiertagsregeln!$D$7:$D$480,MATCH($K27,Feiertagsregeln!$A$7:$A$480,0)) -> Auffahrt | F27: =INDEX(Feiertagsregeln!$E$7:$E$480,MATCH($K27,Feiertagsregeln!$A$7:$A$480,0)) -> Ascension | G27: =IF(INDEX(Feiertagsregeln!$F$7:$F$480,MATCH($K27,Feiertagsregeln!$A$7:$A$480,0))="","Noch zu erfassen",INDEX(Feiertagsregeln!$F$7:$F$480,MATCH($K27,Feiertagsregeln!$A$7:$A$480,0))) -> Noch zu erfassen | H27: =IF(INDEX(Feiertagsregeln!$G$7:$G$480,MATCH($K27,Feiertagsregeln!$A$7:$A$480,0))="","Noch zu erfassen",INDEX(Feiertagsregeln!$G$7:$G$480,MATCH($K27,Feiertagsregeln!$A$7:$A$480,0))) -> Noch zu erfassen | I27: =INDEX(Feiertagsregeln!$H$7:$H$480,MATCH($K27,Feiertagsregeln!$A$7:$A$480,0)) -> labourLawHoliday | J27: open | K27: AG-WORK-HOL-A-ASCENSION | L27: =INDEX(Feiertagsregeln!$Y$7:$Y$480,MATCH($K27,Feiertagsregeln!$A$7:$A$480,0)) -> SRC-AG-EGARR-20250901 | M27: =INDEX(Feiertagsregeln!$Z$7:$Z$480,MATCH($K27,Feiertagsregeln!$A$7:$A$480,0)) -> § 6 Abs. 1 Bst. a | N27: Normliste erfasst, Fachfreigabe offen | O27: =INDEX(Feiertagsregeln!$AA$7:$AA$480,MATCH($K27,Feiertagsregeln!$A$7:$A$480,0)) -> Ganztägig
A28: =INDEX(Feiertagsregeln!$X$7:$X$480,MATCH($K28,Feiertagsregeln!$A$7:$A$480,0)) -> 46909 | B28: =IF(ISNUMBER(A28),CHOOSE(WEEKDAY(A28,2),"Montag","Dienstag","Mittwoch","Donnerstag","Freitag","Samstag","Sonntag")&IF(O28="Ab 12.00 Uhr",", ab 12.00 Uhr",""),"n.a.") -> Montag | C28: CH-AG | D28: Bezirke Aarau, Brugg, Kulm, Lenzburg und Zofingen | E28: =INDEX(Feiertagsregeln!$D$7:$D$480,MATCH($K28,Feiertagsregeln!$A$7:$A$480,0)) -> Pfingstmontag | F28: =INDEX(Feiertagsregeln!$E$7:$E$480,MATCH($K28,Feiertagsregeln!$A$7:$A$480,0)) -> Lundi de Pentecôte | G28: =IF(INDEX(Feiertagsregeln!$F$7:$F$480,MATCH($K28,Feiertagsregeln!$A$7:$A$480,0))="","Noch zu erfassen",INDEX(Feiertagsregeln!$F$7:$F$480,MATCH($K28,Feiertagsregeln!$A$7:$A$480,0))) -> Noch zu erfassen | H28: =IF(INDEX(Feiertagsregeln!$G$7:$G$480,MATCH($K28,Feiertagsregeln!$A$7:$A$480,0))="","Noch zu erfassen",INDEX(Feiertagsregeln!$G$7:$G$480,MATCH($K28,Feiertagsregeln!$A$7:$A$480,0))) -> Noch zu erfassen | I28: =INDEX(Feiertagsregeln!$H$7:$H$480,MATCH($K28,Feiertagsregeln!$A$7:$A$480,0)) -> labourLawHoliday | J28: open | K28: AG-WORK-HOL-A-WHIT-MONDAY | L28: =INDEX(Feiertagsregeln!$Y$7:$Y$480,MATCH($K28,Feiertagsregeln!$A$7:$A$480,0)) -> SRC-AG-EGARR-20250901 | M28: =INDEX(Feiertagsregeln!$Z$7:$Z$480,MATCH($K28,Feiertagsregeln!$A$7:$A$480,0)) -> § 6 Abs. 1 Bst. a | N28: Normliste erfasst, Fachfreigabe offen | O28: =INDEX(Feiertagsregeln!$AA$7:$AA$480,MATCH($K28,Feiertagsregeln!$A$7:$A$480,0)) -> Ganztägig
A29: =INDEX(Feiertagsregeln!$X$7:$X$480,MATCH($K29,Feiertagsregeln!$A$7:$A$480,0)) -> 47112 | B29: =IF(ISNUMBER(A29),CHOOSE(WEEKDAY(A29,2),"Montag","Dienstag","Mittwoch","Donnerstag","Freitag","Samstag","Sonntag")&IF(O29="Ab 12.00 Uhr",", ab 12.00 Uhr",""),"n.a.") -> Montag | C29: CH-AG | D29: Bezirke Aarau, Brugg, Kulm, Lenzburg und Zofingen | E29: =INDEX(Feiertagsregeln!$D$7:$D$480,MATCH($K29,Feiertagsregeln!$A$7:$A$480,0)) -> Weihnachten | F29: =INDEX(Feiertagsregeln!$E$7:$E$480,MATCH($K29,Feiertagsregeln!$A$7:$A$480,0)) -> Noël | G29: =IF(INDEX(Feiertagsregeln!$F$7:$F$480,MATCH($K29,Feiertagsregeln!$A$7:$A$480,0))="","Noch zu erfassen",INDEX(Feiertagsregeln!$F$7:$F$480,MATCH($K29,Feiertagsregeln!$A$7:$A$480,0))) -> Noch zu erfassen | H29: =IF(INDEX(Feiertagsregeln!$G$7:$G$480,MATCH($K29,Feiertagsregeln!$A$7:$A$480,0))="","Noch zu erfassen",INDEX(Feiertagsregeln!$G$7:$G$480,MATCH($K29,Feiertagsregeln!$A$7:$A$480,0))) -> Noch zu erfassen | I29: =INDEX(Feiertagsregeln!$H$7:$H$480,MATCH($K29,Feiertagsregeln!$A$7:$A$480,0)) -> labourLawHoliday | J29: open | K29: AG-WORK-HOL-A-CHRISTMAS | L29: =INDEX(Feiertagsregeln!$Y$7:$Y$480,MATCH($K29,Feiertagsregeln!$A$7:$A$480,0)) -> SRC-AG-EGARR-20250901 | M29: =INDEX(Feiertagsregeln!$Z$7:$Z$480,MATCH($K29,Feiertagsregeln!$A$7:$A$480,0)) -> § 6 Abs. 1 Bst. a | N29: Normliste erfasst, Fachfreigabe offen | O29: =INDEX(Feiertagsregeln!$AA$7:$AA$480,MATCH($K29,Feiertagsregeln!$A$7:$A$480,0)) -> Ganztägig
A30: =INDEX(Feiertagsregeln!$X$7:$X$480,MATCH($K30,Feiertagsregeln!$A$7:$A$480,0)) -> 47113 | B30: =IF(ISNUMBER(A30),CHOOSE(WEEKDAY(A30,2),"Montag","Dienstag","Mittwoch","Donnerstag","Freitag","Samstag","Sonntag")&IF(O30="Ab 12.00 Uhr",", ab 12.00 Uhr",""),"n.a.") -> Dienstag | C30: CH-AG | D30: Bezirke Aarau, Brugg, Kulm, Lenzburg und Zofingen | E30: =INDEX(Feiertagsregeln!$D$7:$D$480,MATCH($K30,Feiertagsregeln!$A$7:$A$480,0)) -> Stephanstag | F30: =INDEX(Feiertagsregeln!$E$7:$E$480,MATCH($K30,Feiertagsregeln!$A$7:$A$480,0)) -> Saint-Étienne | G30: =IF(INDEX(Feiertagsregeln!$F$7:$F$480,MATCH($K30,Feiertagsregeln!$A$7:$A$480,0))="","Noch zu erfassen",INDEX(Feiertagsregeln!$F$7:$F$480,MATCH($K30,Feiertagsregeln!$A$7:$A$480,0))) -> Noch zu erfassen | H30: =IF(INDEX(Feiertagsregeln!$G$7:$G$480,MATCH($K30,Feiertagsregeln!$A$7:$A$480,0))="","Noch zu erfassen",INDEX(Feiertagsregeln!$G$7:$G$480,MATCH($K30,Feiertagsregeln!$A$7:$A$480,0))) -> Noch zu erfassen | I30: =INDEX(Feiertagsregeln!$H$7:$H$480,MATCH($K30,Feiertagsregeln!$A$7:$A$480,0)) -> labourLawHoliday | J30: open | K30: AG-WORK-HOL-A-ST-STEPHEN | L30: =INDEX(Feiertagsregeln!$Y$7:$Y$480,MATCH($K30,Feiertagsregeln!$A$7:$A$480,0)) -> SRC-AG-EGARR-20250901 | M30: =INDEX(Feiertagsregeln!$Z$7:$Z$480,MATCH($K30,Feiertagsregeln!$A$7:$A$480,0)) -> § 6 Abs. 1 Bst. a | N30: Normliste erfasst, Fachfreigabe offen | O30: =INDEX(Feiertagsregeln!$AA$7:$AA$480,MATCH($K30,Feiertagsregeln!$A$7:$A$480,0)) -> Ganztägig
A31: =INDEX(Feiertagsregeln!$X$7:$X$480,MATCH($K31,Feiertagsregeln!$A$7:$A$480,0)) -> 46753 | B31: =IF(ISNUMBER(A31),CHOOSE(WEEKDAY(A31,2),"Montag","Dienstag","Mittwoch","Donnerstag","Freitag","Samstag","Sonntag")&IF(O31="Ab 12.00 Uhr",", ab 12.00 Uhr",""),"n.a.") -> Samstag | C31: CH-AG | D31: Gemeinde Bergdietikon | E31: =INDEX(Feiertagsregeln!$D$7:$D$480,MATCH($K31,Feiertagsregeln!$A$7:$A$480,0)) -> Neujahr | F31: =INDEX(Feiertagsregeln!$E$7:$E$480,MATCH($K31,Feiertagsregeln!$A$7:$A$480,0)) -> Nouvel An | G31: =IF(INDEX(Feiertagsregeln!$F$7:$F$480,MATCH($K31,Feiertagsregeln!$A$7:$A$480,0))="","Noch zu erfassen",INDEX(Feiertagsregeln!$F$7:$F$480,MATCH($K31,Feiertagsregeln!$A$7:$A$480,0))) -> Noch zu erfassen | H31: =IF(INDEX(Feiertagsregeln!$G$7:$G$480,MATCH($K31,Feiertagsregeln!$A$7:$A$480,0))="","Noch zu erfassen",INDEX(Feiertagsregeln!$G$7:$G$480,MATCH($K31,Feiertagsregeln!$A$7:$A$480,0))) -> Noch zu erfassen | I31: =INDEX(Feiertagsregeln!$H$7:$H$480,MATCH($K31,Feiertagsregeln!$A$7:$A$480,0)) -> labourLawHoliday | J31: open | K31: AG-WORK-HOL-B1-NEW-YEAR | L31: =INDEX(Feiertagsregeln!$Y$7:$Y$480,MATCH($K31,Feiertagsregeln!$A$7:$A$480,0)) -> SRC-AG-EGARR-20250901 | M31: =INDEX(Feiertagsregeln!$Z$7:$Z$480,MATCH($K31,Feiertagsregeln!$A$7:$A$480,0)) -> § 6 Abs. 1 Bst. b Ziff. 1 | N31: Normliste erfasst, Fachfreigabe offen | O31: =INDEX(Feiertagsregeln!$AA$7:$AA$480,MATCH($K31,Feiertagsregeln!$A$7:$A$480,0)) -> Ganztägig
... A489: =INDEX(Feiertagsregeln!$X$7:$X$480,MATCH($K489,Feiertagsregeln!$A$7:$A$480,0)) -> 47112 | B489: =IF(ISNUMBER(A489),CHOOSE(WEEKDAY(A489,2),"Montag","Dienstag","Mittwoch","Donnerstag","Freitag","Samstag","Sonntag")&IF(O489="Ab 12.00 Uhr",", ab 12.00 Uhr",""),"n.a.") -> Montag | C489: CH-JU | D489: Jura, arbeitsrechtliche Liste nach Art. 4 | E489: =INDEX(Feiertagsregeln!$D$7:$D$480,MATCH($K489,Feiertagsregeln!$A$7:$A$480,0)) -> Weihnachten | F489: =INDEX(Feiertagsregeln!$E$7:$E$480,MATCH($K489,Feiertagsregeln!$A$7:$A$480,0)) -> Noël | G489: =IF(INDEX(Feiertagsregeln!$F$7:$F$480,MATCH($K489,Feiertagsregeln!$A$7:$A$480,0))="","Noch zu erfassen",INDEX(Feiertagsregeln!$F$7:$F$480,MATCH($K489,Feiertagsregeln!$A$7:$A$480,0))) -> Natale | H489: =IF(INDEX(Feiertagsregeln!$G$7:$G$480,MATCH($K489,Feiertagsregeln!$A$7:$A$480,0))="","Noch zu erfassen",INDEX(Feiertagsregeln!$G$7:$G$480,MATCH($K489,Feiertagsregeln!$A$7:$A$480,0))) -> Di da Nadal | I489: =INDEX(Feiertagsregeln!$H$7:$H$480,MATCH($K489,Feiertagsregeln!$A$7:$A$480,0)) -> labourLawHoliday | J489: open | K489: JU-LJF-LABOUR-DAY-CHRISTMAS | L489: =INDEX(Feiertagsregeln!$Y$7:$Y$480,MATCH($K489,Feiertagsregeln!$A$7:$A$480,0)) -> SRC-JU-LJF-5551-20230101 | M489: =INDEX(Feiertagsregeln!$Z$7:$Z$480,MATCH($K489,Feiertagsregeln!$A$7:$A$480,0)) -> Art. 4 | N489: Erfassungsentwurf. Keine neue Fristenprofilfreigabe. | O489: =INDEX(Feiertagsregeln!$AA$7:$AA$480,MATCH($K489,Feiertagsregeln!$A$7:$A$480,0)) -> Ganztägig

Sheet Gemeinwesen
A2: Gemeinwesen und Bearbeitungsstand
A4: Erfassungsstand und fachliche Freigabe sind getrennt. Leere Quellen sind noch zu erheben.
A6: Code | B6: Deutsch | C6: Französisch | D6: Italienisch | E6: Rumantsch Grischun | F6: Übergeordnet | G6: Erfassungsstand | H6: Fachstatus | I6: Amtliche Feiertagsquelle
A7: CH | B7: Bund | C7: Confédération | G7: Referenzpilot | H7: approved | I7: https://www.fedlex.admin.ch/eli/cc/1994/1340_1340_1340/de
A8: CH-ZH | B8: Zürich | C8: Zurich | D8: Zurigo | E8: Turitg | F8: CH | G8: AP18B-04, Normlisten erfasst, Fachabnahme offen | H8: open | I8: https://www.notes.zh.ch/appl/zhlex_r.nsf/WebView/663A7F8F1929F218C1256EB7002E6A05/%24File/822.4_26.6.00_45.pdf
A9: CH-BE | B9: Bern | C9: Berne | F9: CH | G9: Referenzpilot | H9: approved | I9: https://www.belex.sites.be.ch/app/de/texts_of_law/555.1
A10: CH-LU | B10: Luzern | C10: Lucerne | D10: Lucerna | E10: Lucerna | F10: CH | G10: AP18B-04, Normlisten erfasst, Fachabnahme offen | H10: open | I10: https://srl.lu.ch/data/855/de
A11: CH-UR | B11: Uri | C11: Uri | D11: Uri | E11: Uri | F11: CH | G11: AP18B-04, Normlisten erfasst, Fachabnahme offen | H11: open | I11: https://rechtsbuch.ur.ch/api/de/versions/963/pdf_file
A12: CH-SZ | B12: Schwyz | C12: Schwytz | D12: Svitto | E12: Sviz | F12: CH | G12: AP18B-04, Normlisten erfasst, Fachabnahme offen | H12: open | I12: https://www.sz.ch/public/upload/assets/28055/545_110.pdf
A13: CH-OW | B13: Obwalden | C13: Obwald | D13: Obvaldo | E13: Sursilvania | F13: CH | G13: AP18B-04, Normlisten erfasst, Fachabnahme offen | H13: open | I13: https://gdb.ow.ch/api/de/versions/103/pdf_file
A14: CH-NW | B14: Nidwalden | C14: Nidwald | D14: Nidvaldo | E14: Sutsilvania | F14: CH | G14: AP18B-04, Normlisten erfasst, Fachabnahme offen | H14: open | I14: https://gesetze.nw.ch/app/de/texts_of_law/921.1
A15: CH-GL | B15: Glarus | C15: Glaris | D15: Glarona | E15: Glaruna | F15: CH | G15: AP18B-04, Teilerfassung mit dokumentierter Lücke, Fachabnahme offen | H15: open | I15: https://gesetze.gl.ch/api/de/versions/2110/pdf_file
A16: CH-ZG | B16: Zug | C16: Zoug | D16: Zugo | E16: Zug | F16: CH | G16: AP18B-04, Normlisten erfasst, Fachabnahme offen | H16: open | I16: https://bgs.zg.ch/app/de/texts_of_law/942.31
A17: CH-FR | B17: Freiburg | C17: Fribourg | D17: Friburgo | E17: Friburg | F17: CH | G17: AP18B-03, kantonale Normlisten erfasst, Fachabnahme offen | H17: open | I17: https://bdlf.fr.ch/api/de/versions/8126/pdf_file
A18: CH-SO | B18: Solothurn | C18: Soleure | D18: Soletta | E18: Soloturn | F18: CH | G18: AP18B-03, kantonale Normlisten erfasst, Fachabnahme offen | H18: open | I18: https://bgs.so.ch/api/de/versions/4319/pdf_file
A19: CH-BS | B19: Basel-Stadt | C19: Bâle-Ville | D19: Basilea Città | E19: Basilea-Citad | F19: CH | G19: AP18B-04, Normlisten erfasst, Fachabnahme offen | H19: open | I19: https://www.gesetzessammlung.bs.ch/frontend/versions/4927/download_pdf_file?locale=de
A20: CH-BL | B20: Basel-Landschaft | C20: Bâle-Campagne | D20: Basilea Campagna | E20: Basilea-Champagna | F20: CH | G20: AP18B-04, Normlisten erfasst, Fachabnahme offen | H20: open | I20: https://bl.clex.ch/api/versions/2507/pdf_file_with_annexes
A21: CH-SH | B21: Schaffhausen | C21: Schaffhouse | D21: Sciaffusa | E21: Schaffusa | F21: CH | G21: AP18B-04, Normlisten erfasst, Fachabnahme offen | H21: open | I21: https://rechtsbuch.sh.ch/api/de/versions/1886/pdf_file
... A25: CH-GR | B25: Graubünden | C25: Grisons | D25: Grigioni | E25: Grischun | F25: CH | G25: AP18B-02, kantonale Normliste erfasst, Fachabnahme offen | H25: open | I25: https://www.gr-lex.gr.ch/api/de/versions/2604/pdf_file
A26: CH-AG | B26: Aargau | C26: Argovie | F26: CH | G26: Kantonspaket AP18B-01, Fachabnahme offen | H26: open | I26: https://gesetzessammlungen.ag.ch/app/de/texts_of_law/961.200
A27: CH-TG | B27: Thurgau | C27: Thurgovie | D27: Turgovia | E27: Turgovia | F27: CH | G27: AP18B-04, Normlisten erfasst, Fachabnahme offen | H27: open | I27: https://www.rechtsbuch.tg.ch/api/de/versions/2949/pdf_file
A28: CH-TI | B28: Tessin | C28: Tessin | D28: Ticino | E28: Tessin | F28: CH | G28: AP18B-02, kantonale Normliste erfasst, Fachabnahme offen | H28: open | I28: https://www3.ti.ch/CAN/RLeggi/public/index.php/raccolta-leggi/legge/num/568
A29: CH-VD | B29: Waadt | C29: Vaud | D29: Vaud | E29: Vad | F29: CH | G29: AP18B-04, Normlisten erfasst, Fachabnahme offen | H29: open | I29: https://prestations.vd.ch/pub/blv-publication/actes/consolide/822.11?id=c3ef83f5-e736-490d-90a7-1753b31d5ef3
A30: CH-VS | B30: Wallis | C30: Valais | D30: Vallese | E30: Vallais | F30: CH | G30: AP18B-03, kantonale Normlisten erfasst, Fachabnahme offen | H30: open | I30: https://lex.vs.ch/api/de/versions/2105/pdf_file
A31: CH-NE | B31: Neuenburg | C31: Neuchâtel | D31: Neuchâtel | E31: Neuchâtel | F31: CH | G31: AP18B-04, Teilerfassung mit dokumentierter Lücke, Fachabnahme offen | H31: open | I31: https://rsn.ne.ch/DATA/program/books/rsne/pdf/941.02.pdf
A32: CH-GE | B32: Genf | C32: Genève | D32: Ginevra | E32: Genevra | F32: CH | G32: AP18B-03, kantonale Normlisten erfasst, Fachabnahme offen | H32: open | I32: https://silgeneve.ch/legis/data/rsg_j1_45.htm
A33: CH-JU | B33: Jura | C33: Jura | D33: Giura | E33: Giura | F33: CH | G33: AP18B-04, Normlisten erfasst, Fachabnahme offen | H33: open | I33: https://rsju.jura.ch/Htdocs/Files/v/38948.pdf

Sheet Feiertagsregeln
A2: Feiertagsregeln und Berechnung
A4: Rechtskategorie und Geltungsbereich sind Pflicht. Datum und Gültigkeit rechts werden aus dem Kalenderjahr berechnet.
A6: Regel-ID | B6: Gemeinwesen | C6: Geltungs-ID | D6: Deutsch | E6: Französisch | F6: Italienisch | G6: Rumantsch Grischun | H6: Rechtskategorie | I6: Regeltyp | J6: Monat | K6: Tag | L6: Tagesabstand | M6: ISO-Wochentag | N6: Vorkommen | O6: Gültig ab | P6: Gültig bis | Q6: Priorität | R6: Fachstatus | S6: Freigabebasis | T6: Wirkung | U6: Zielregel | V6: Exportklasse | W6: Rohdatum | X6: Datum im Geltungszeitraum | Y6: Quellen-ID | Z6: Fundstelle | AA6: Tagesumfang | AC6: Osterrechnung | AD6: Wert
A7: CH-CAL-HOL-NATIONAL-DAY | B7: CH | C7: CH-ALL | D7: Bundesfeiertag | E7: Fête nationale | H7: publicHoliday | I7: fixedMonthDay | J7: 8 | K7: 1 | O7: 34516 | Q7: 100 | R7: approved | S7: 2026-08-31-mvp-03-approved.1 | T7: add | V7: referenceOnly | W7: =IF(AND(ISNUMBER(Übersicht!$B$4),Übersicht!$B$4=INT(Übersicht!$B$4),Übersicht!$B$4>=2026,Übersicht!$B$4<=2028),IF(I7="fixedMonthDay",IF(AND(ISNUMBER(J7),J7=INT(J7),J7>=1,J7<=12,ISNUMBER(K7),K7=INT(K7),K7>=1,K7<=31,MONTH(DATE(Übersicht!$B$4,J7,K7))=J7,DAY(DATE(Übersicht!$B$4,J7,K7))=K7,L7="",M7="",N7=""),DATE(Übersicht!$B$4,J7,K7),NA()),IF(I7="easterOffsetDays",IF(AND(ISNUMBER(L7),L7=INT(L7),L7>=-366,L7<=366,J7="",K7="",M7="",N7=""),$AD$23+L7,NA()),IF(I7="nthWeekdayOfMonth",IF(AND(ISNUMBER(J7),J7=INT(J7),J7>=1,J7<=12,ISNUMBER(M7),M7=INT(M7),M7>=1,M7<=7,ISNUMBER(N7),N7=INT(N7),N7>=1,N7<=5,MONTH(DATE(Übersicht!$B$4,J7,1)+MOD(M7-WEEKDAY(DATE(Übersicht!$B$4,J7,1),2),7)+7*(N7-1))=J7,K7="",L7=""),DATE(Übersicht!$B$4,J7,1)+MOD(M7-WEEKDAY(DATE(Übersicht!$B$4,J7,1),2),7)+7*(N7-1),NA()),IF(I7="nthWeekdayOffsetDays",IF(AND(ISNUMBER(J7),J7=INT(J7),J7>=1,J7<=12,ISNUMBER(M7),M7=INT(M7),M7>=1,M7<=7,ISNUMBER(N7),N7=INT(N7),N7>=1,N7<=5,MONTH(DATE(Übersicht!$B$4,J7,1)+MOD(M7-WEEKDAY(DATE(Übersicht!$B$4,J7,1),2),7)+7*(N7-1))=J7,K7="",ISNUMBER(L7),L7=INT(L7),L7>=-366,L7<=366),DATE(Übersicht!$B$4,J7,1)+MOD(M7-WEEKDAY(DATE(Übersicht!$B$4,J7,1),2),7)+7*(N7-1)+L7,NA()),NA())))),NA()) -> 46966 | X7: =IF(AND(ISNUMBER(O7),O7=INT(O7),O7>=-115780,O7<=2958465,OR(P7="",AND(ISNUMBER(P7),P7=INT(P7),P7>=-115780,P7<=2958465,P7>=O7)),OR(AA7="Ganztägig",AA7="Ab 12.00 Uhr")),IF(AND(W7>=O7,OR(P7="",W7<=P7)),W7,"Ausserhalb Geltung"),NA()) -> 46966 | Y7: SRC-BUNDESFEIERTAG-19940701 | Z7: Art. 1 | AA7: Ganztägig | AC7: Jahr | AD7: =Übersicht!$B$4 -> 2028
A8: BE-CAL-HOL-NEW-YEAR | B8: CH-BE | C8: BE-ALL | D8: Neujahr | E8: Nouvel An | H8: publicHoliday | I8: fixedMonthDay | J8: 1 | K8: 1 | O8: 46023 | Q8: 100 | R8: approved | S8: 2026-08-31-mvp-03-approved.1 | T8: add | V8: referenceOnly | W8: =IF(AND(ISNUMBER(Übersicht!$B$4),Übersicht!$B$4=INT(Übersicht!$B$4),Übersicht!$B$4>=2026,Übersicht!$B$4<=2028),IF(I8="fixedMonthDay",IF(AND(ISNUMBER(J8),J8=INT(J8),J8>=1,J8<=12,ISNUMBER(K8),K8=INT(K8),K8>=1,K8<=31,MONTH(DATE(Übersicht!$B$4,J8,K8))=J8,DAY(DATE(Übersicht!$B$4,J8,K8))=K8,L8="",M8="",N8=""),DATE(Übersicht!$B$4,J8,K8),NA()),IF(I8="easterOffsetDays",IF(AND(ISNUMBER(L8),L8=INT(L8),L8>=-366,L8<=366,J8="",K8="",M8="",N8=""),$AD$23+L8,NA()),IF(I8="nthWeekdayOfMonth",IF(AND(ISNUMBER(J8),J8=INT(J8),J8>=1,J8<=12,ISNUMBER(M8),M8=INT(M8),M8>=1,M8<=7,ISNUMBER(N8),N8=INT(N8),N8>=1,N8<=5,MONTH(DATE(Übersicht!$B$4,J8,1)+MOD(M8-WEEKDAY(DATE(Übersicht!$B$4,J8,1),2),7)+7*(N8-1))=J8,K8="",L8=""),DATE(Übersicht!$B$4,J8,1)+MOD(M8-WEEKDAY(DATE(Übersicht!$B$4,J8,1),2),7)+7*(N8-1),NA()),IF(I8="nthWeekdayOffsetDays",IF(AND(ISNUMBER(J8),J8=INT(J8),J8>=1,J8<=12,ISNUMBER(M8),M8=INT(M8),M8>=1,M8<=7,ISNUMBER(N8),N8=INT(N8),N8>=1,N8<=5,MONTH(DATE(Übersicht!$B$4,J8,1)+MOD(M8-WEEKDAY(DATE(Übersicht!$B$4,J8,1),2),7)+7*(N8-1))=J8,K8="",ISNUMBER(L8),L8=INT(L8),L8>=-366,L8<=366),DATE(Übersicht!$B$4,J8,1)+MOD(M8-WEEKDAY(DATE(Übersicht!$B$4,J8,1),2),7)+7*(N8-1)+L8,NA()),NA())))),NA()) -> 46753 | X8: =IF(AND(ISNUMBER(O8),O8=INT(O8),O8>=-115780,O8<=2958465,OR(P8="",AND(ISNUMBER(P8),P8=INT(P8),P8>=-115780,P8<=2958465,P8>=O8)),OR(AA8="Ganztägig",AA8="Ab 12.00 Uhr")),IF(AND(W8>=O8,OR(P8="",W8<=P8)),W8,"Ausserhalb Geltung"),NA()) -> 46753 | Y8: SRC-FRG-BE-20210401 | Z8: Art. 2 Abs. 1 Bst. c | AA8: Ganztägig | AC8: a | AD8: =MOD(AD7,19) -> 14
A9: BE-CAL-HOL-BERCHTOLD-DAY | B9: CH-BE | C9: BE-ALL | D9: Berchtoldstag | E9: Saint-Berchtold | H9: publicHoliday | I9: fixedMonthDay | J9: 1 | K9: 2 | O9: 46023 | Q9: 100 | R9: approved | S9: 2026-08-31-mvp-03-approved.1 | T9: add | V9: referenceOnly | W9: =IF(AND(ISNUMBER(Übersicht!$B$4),Übersicht!$B$4=INT(Übersicht!$B$4),Übersicht!$B$4>=2026,Übersicht!$B$4<=2028),IF(I9="fixedMonthDay",IF(AND(ISNUMBER(J9),J9=INT(J9),J9>=1,J9<=12,ISNUMBER(K9),K9=INT(K9),K9>=1,K9<=31,MONTH(DATE(Übersicht!$B$4,J9,K9))=J9,DAY(DATE(Übersicht!$B$4,J9,K9))=K9,L9="",M9="",N9=""),DATE(Übersicht!$B$4,J9,K9),NA()),IF(I9="easterOffsetDays",IF(AND(ISNUMBER(L9),L9=INT(L9),L9>=-366,L9<=366,J9="",K9="",M9="",N9=""),$AD$23+L9,NA()),IF(I9="nthWeekdayOfMonth",IF(AND(ISNUMBER(J9),J9=INT(J9),J9>=1,J9<=12,ISNUMBER(M9),M9=INT(M9),M9>=1,M9<=7,ISNUMBER(N9),N9=INT(N9),N9>=1,N9<=5,MONTH(DATE(Übersicht!$B$4,J9,1)+MOD(M9-WEEKDAY(DATE(Übersicht!$B$4,J9,1),2),7)+7*(N9-1))=J9,K9="",L9=""),DATE(Übersicht!$B$4,J9,1)+MOD(M9-WEEKDAY(DATE(Übersicht!$B$4,J9,1),2),7)+7*(N9-1),NA()),IF(I9="nthWeekdayOffsetDays",IF(AND(ISNUMBER(J9),J9=INT(J9),J9>=1,J9<=12,ISNUMBER(M9),M9=INT(M9),M9>=1,M9<=7,ISNUMBER(N9),N9=INT(N9),N9>=1,N9<=5,MONTH(DATE(Übersicht!$B$4,J9,1)+MOD(M9-WEEKDAY(DATE(Übersicht!$B$4,J9,1),2),7)+7*(N9-1))=J9,K9="",ISNUMBER(L9),L9=INT(L9),L9>=-366,L9<=366),DATE(Übersicht!$B$4,J9,1)+MOD(M9-WEEKDAY(DATE(Übersicht!$B$4,J9,1),2),7)+7*(N9-1)+L9,NA()),NA())))),NA()) -> 46754 | X9: =IF(AND(ISNUMBER(O9),O9=INT(O9),O9>=-115780,O9<=2958465,OR(P9="",AND(ISNUMBER(P9),P9=INT(P9),P9>=-115780,P9<=2958465,P9>=O9)),OR(AA9="Ganztägig",AA9="Ab 12.00 Uhr")),IF(AND(W9>=O9,OR(P9="",W9<=P9)),W9,"Ausserhalb Geltung"),NA()) -> 46754 | Y9: SRC-FRG-BE-20210401 | Z9: Art. 2 Abs. 1 Bst. c | AA9: Ganztägig | AC9: b | AD9: =INT(AD7/100) -> 20
A10: BE-CAL-HOL-GOOD-FRIDAY | B10: CH-BE | C10: BE-ALL | D10: Karfreitag | E10: Vendredi saint | H10: publicHoliday | I10: easterOffsetDays | L10: -2 | O10: 46023 | Q10: 100 | R10: approved | S10: 2026-08-31-mvp-03-approved.1 | T10: add | V10: referenceOnly | W10: =IF(AND(ISNUMBER(Übersicht!$B$4),Übersicht!$B$4=INT(Übersicht!$B$4),Übersicht!$B$4>=2026,Übersicht!$B$4<=2028),IF(I10="fixedMonthDay",IF(AND(ISNUMBER(J10),J10=INT(J10),J10>=1,J10<=12,ISNUMBER(K10),K10=INT(K10),K10>=1,K10<=31,MONTH(DATE(Übersicht!$B$4,J10,K10))=J10,DAY(DATE(Übersicht!$B$4,J10,K10))=K10,L10="",M10="",N10=""),DATE(Übersicht!$B$4,J10,K10),NA()),IF(I10="easterOffsetDays",IF(AND(ISNUMBER(L10),L10=INT(L10),L10>=-366,L10<=366,J10="",K10="",M10="",N10=""),$AD$23+L10,NA()),IF(I10="nthWeekdayOfMonth",IF(AND(ISNUMBER(J10),J10=INT(J10),J10>=1,J10<=12,ISNUMBER(M10),M10=INT(M10),M10>=1,M10<=7,ISNUMBER(N10),N10=INT(N10),N10>=1,N10<=5,MONTH(DATE(Übersicht!$B$4,J10,1)+MOD(M10-WEEKDAY(DATE(Übersicht!$B$4,J10,1),2),7)+7*(N10-1))=J10,K10="",L10=""),DATE(Übersicht!$B$4,J10,1)+MOD(M10-WEEKDAY(DATE(Übersicht!$B$4,J10,1),2),7)+7*(N10-1),NA()),IF(I10="nthWeekdayOffsetDays",IF(AND(ISNUMBER(J10),J10=INT(J10),J10>=1,J10<=12,ISNUMBER(M10),M10=INT(M10),M10>=1,M10<=7,ISNUMBER(N10),N10=INT(N10),N10>=1,N10<=5,MONTH(DATE(Übersicht!$B$4,J10,1)+MOD(M10-WEEKDAY(DATE(Übersicht!$B$4,J10,1),2),7)+7*(N10-1))=J10,K10="",ISNUMBER(L10),L10=INT(L10),L10>=-366,L10<=366),DATE(Übersicht!$B$4,J10,1)+MOD(M10-WEEKDAY(DATE(Übersicht!$B$4,J10,1),2),7)+7*(N10-1)+L10,NA()),NA())))),NA()) -> 46857 | X10: =IF(AND(ISNUMBER(O10),O10=INT(O10),O10>=-115780,O10<=2958465,OR(P10="",AND(ISNUMBER(P10),P10=INT(P10),P10>=-115780,P10<=2958465,P10>=O10)),OR(AA10="Ganztägig",AA10="Ab 12.00 Uhr")),IF(AND(W10>=O10,OR(P10="",W10<=P10)),W10,"Ausserhalb Geltung"),NA()) -> 46857 | Y10: SRC-FRG-BE-20210401 | Z10: Art. 2 Abs. 1 Bst. b | AA10: Ganztägig | AC10: c | AD10: =MOD(AD7,100) -> 28
A11: BE-CAL-HOL-EASTER | B11: CH-BE | C11: BE-ALL | D11: Ostern | E11: Pâques | H11: publicHoliday | I11: easterOffsetDays | L11: 0 | O11: 46023 | Q11: 100 | R11: approved | S11: 2026-08-31-mvp-03-approved.1 | T11: add | V11: referenceOnly | W11: =IF(AND(ISNUMBER(Übersicht!$B$4),Übersicht!$B$4=INT(Übersicht!$B$4),Übersicht!$B$4>=2026,Übersicht!$B$4<=2028),IF(I11="fixedMonthDay",IF(AND(ISNUMBER(J11),J11=INT(J11),J11>=1,J11<=12,ISNUMBER(K11),K11=INT(K11),K11>=1,K11<=31,MONTH(DATE(Übersicht!$B$4,J11,K11))=J11,DAY(DATE(Übersicht!$B$4,J11,K11))=K11,L11="",M11="",N11=""),DATE(Übersicht!$B$4,J11,K11),NA()),IF(I11="easterOffsetDays",IF(AND(ISNUMBER(L11),L11=INT(L11),L11>=-366,L11<=366,J11="",K11="",M11="",N11=""),$AD$23+L11,NA()),IF(I11="nthWeekdayOfMonth",IF(AND(ISNUMBER(J11),J11=INT(J11),J11>=1,J11<=12,ISNUMBER(M11),M11=INT(M11),M11>=1,M11<=7,ISNUMBER(N11),N11=INT(N11),N11>=1,N11<=5,MONTH(DATE(Übersicht!$B$4,J11,1)+MOD(M11-WEEKDAY(DATE(Übersicht!$B$4,J11,1),2),7)+7*(N11-1))=J11,K11="",L11=""),DATE(Übersicht!$B$4,J11,1)+MOD(M11-WEEKDAY(DATE(Übersicht!$B$4,J11,1),2),7)+7*(N11-1),NA()),IF(I11="nthWeekdayOffsetDays",IF(AND(ISNUMBER(J11),J11=INT(J11),J11>=1,J11<=12,ISNUMBER(M11),M11=INT(M11),M11>=1,M11<=7,ISNUMBER(N11),N11=INT(N11),N11>=1,N11<=5,MONTH(DATE(Übersicht!$B$4,J11,1)+MOD(M11-WEEKDAY(DATE(Übersicht!$B$4,J11,1),2),7)+7*(N11-1))=J11,K11="",ISNUMBER(L11),L11=INT(L11),L11>=-366,L11<=366),DATE(Übersicht!$B$4,J11,1)+MOD(M11-WEEKDAY(DATE(Übersicht!$B$4,J11,1),2),7)+7*(N11-1)+L11,NA()),NA())))),NA()) -> 46859 | X11: =IF(AND(ISNUMBER(O11),O11=INT(O11),O11>=-115780,O11<=2958465,OR(P11="",AND(ISNUMBER(P11),P11=INT(P11),P11>=-115780,P11<=2958465,P11>=O11)),OR(AA11="Ganztägig",AA11="Ab 12.00 Uhr")),IF(AND(W11>=O11,OR(P11="",W11<=P11)),W11,"Ausserhalb Geltung"),NA()) -> 46859 | Y11: SRC-FRG-BE-20210401 | Z11: Art. 2 Abs. 1 Bst. b | AA11: Ganztägig | AC11: d | AD11: =INT(AD9/4) -> 5
A12: BE-CAL-HOL-EASTER-MONDAY | B12: CH-BE | C12: BE-ALL | D12: Ostermontag | E12: Lundi de Pâques | H12: publicHoliday | I12: easterOffsetDays | L12: 1 | O12: 46023 | Q12: 100 | R12: approved | S12: 2026-08-31-mvp-03-approved.1 | T12: add | V12: referenceOnly | W12: =IF(AND(ISNUMBER(Übersicht!$B$4),Übersicht!$B$4=INT(Übersicht!$B$4),Übersicht!$B$4>=2026,Übersicht!$B$4<=2028),IF(I12="fixedMonthDay",IF(AND(ISNUMBER(J12),J12=INT(J12),J12>=1,J12<=12,ISNUMBER(K12),K12=INT(K12),K12>=1,K12<=31,MONTH(DATE(Übersicht!$B$4,J12,K12))=J12,DAY(DATE(Übersicht!$B$4,J12,K12))=K12,L12="",M12="",N12=""),DATE(Übersicht!$B$4,J12,K12),NA()),IF(I12="easterOffsetDays",IF(AND(ISNUMBER(L12),L12=INT(L12),L12>=-366,L12<=366,J12="",K12="",M12="",N12=""),$AD$23+L12,NA()),IF(I12="nthWeekdayOfMonth",IF(AND(ISNUMBER(J12),J12=INT(J12),J12>=1,J12<=12,ISNUMBER(M12),M12=INT(M12),M12>=1,M12<=7,ISNUMBER(N12),N12=INT(N12),N12>=1,N12<=5,MONTH(DATE(Übersicht!$B$4,J12,1)+MOD(M12-WEEKDAY(DATE(Übersicht!$B$4,J12,1),2),7)+7*(N12-1))=J12,K12="",L12=""),DATE(Übersicht!$B$4,J12,1)+MOD(M12-WEEKDAY(DATE(Übersicht!$B$4,J12,1),2),7)+7*(N12-1),NA()),IF(I12="nthWeekdayOffsetDays",IF(AND(ISNUMBER(J12),J12=INT(J12),J12>=1,J12<=12,ISNUMBER(M12),M12=INT(M12),M12>=1,M12<=7,ISNUMBER(N12),N12=INT(N12),N12>=1,N12<=5,MONTH(DATE(Übersicht!$B$4,J12,1)+MOD(M12-WEEKDAY(DATE(Übersicht!$B$4,J12,1),2),7)+7*(N12-1))=J12,K12="",ISNUMBER(L12),L12=INT(L12),L12>=-366,L12<=366),DATE(Übersicht!$B$4,J12,1)+MOD(M12-WEEKDAY(DATE(Übersicht!$B$4,J12,1),2),7)+7*(N12-1)+L12,NA()),NA())))),NA()) -> 46860 | X12: =IF(AND(ISNUMBER(O12),O12=INT(O12),O12>=-115780,O12<=2958465,OR(P12="",AND(ISNUMBER(P12),P12=INT(P12),P12>=-115780,P12<=2958465,P12>=O12)),OR(AA12="Ganztägig",AA12="Ab 12.00 Uhr")),IF(AND(W12>=O12,OR(P12="",W12<=P12)),W12,"Ausserhalb Geltung"),NA()) -> 46860 | Y12: SRC-FRG-BE-20210401 | Z12: Art. 2 Abs. 1 Bst. c | AA12: Ganztägig | AC12: e | AD12: =MOD(AD9,4) -> 0
